Workbook

Sheet 27JulyTo15Nov_All
A1: Start Date | B1: End Date | C1: Portfolio name | D1: Currency | E1: Campaign Name | F1: Ad Group Name | G1: Country | H1: Targeting | I1: Match Type | J1: Customer Search Term | K1: Impressions | L1: Clicks | M1: Click-Thru Rate (CTR) | N1: Cost Per Click (CPC) | O1: Spend | P1: 7 Day Total Sales | Q1: Total Advertising Cost of Sales (ACOS) | R1: Total Return on Advertising Spend (ROAS) | S1: 7 Day Total Orders (#) | T1: 7 Day Total Units (#) | U1: 7 Day Conversion Rate | V1: 7 Day Advertised SKU Units (#) | W1: 7 Day Other SKU Units (#) | X1: 7 Day Advertised SKU Sales | Y1: 7 Day Other SKU Sales | Z1: Week Number | AA1: Acos
A2: 45976 | B2: 45976 | C2: SP BROAD SEED | D2: USD | E2: SP MACA ROOT KW ASHWAGANDHA BROAD GA 29102022 | F2: ashwagandha | G2: United States | H2: ashwagandha | I2: BROAD | J2: ashwagandha coq10 | K2: 1 | L2: 1 | M2: 1 | N2: $2.83 | O2: 2.83 | P2: 24.94 | Q2: 11.35 | R2: 8.81 | S2: 1 | T2: 1 | U2: 1 | V2: 1 | W2: 0 | X2: $24.94 | Y2: $0.00
A3: 45975 | B3: 45975 | C3: SP BROAD SEED | D3: USD | E3: SP MACA ROOT KW ASHWAGANDHA BROAD GA 29102022 | F3: ashwagandha | G3: United States | H3: ashwagandha | I3: BROAD | J3: ashwagandha pills for men | K3: 1 | L3: 1 | M3: 1 | N3: $4.48 | O3: 4.48 | P3: 24.94 | Q3: 17.96 | R3: 5.57 | S3: 1 | T3: 1 | U3: 1 | V3: 1 | W3: 0 | X3: $24.94 | Y3: $0.00
A4: 45975 | B4: 45975 | C4: SP BROAD SEED | D4: USD | E4: SP MACA ROOT KW ASHWAGANDHA BROAD GA 29102022 | F4: ashwagandha | G4: United States | H4: ashwagandha | I4: BROAD | J4: maca amd ashwagandha | K4: 2 | L4: 1 | M4: 0.5 | N4: $4.48 | O4: 4.48 | P4: 24.94 | Q4: 17.96 | R4: 5.57 | S4: 1 | T4: 1 | U4: 1 | V4: 1 | W4: 0 | X4: $24.94 | Y4: $0.00
A5: 45975 | B5: 45975 | C5: SP TOS | D5: USD | E5: SP TOS MACA ASHWA KW RANK GA 04042024 | F5: MACA ASHWAGANDHA | G5: United States | H5: maca root ashwagandha | I5: PHRASE | J5: magnesium zinc maca root ashwagandha | K5: 1 | L5: 1 | M5: 1 | N5: $3.19 | O5: 3.19 | P5: 99.76 | Q5: 3.2 | R5: 31.27 | S5: 1 | T5: 4 | U5: 1 | V5: 4 | W5: 0 | X5: $99.76 | Y5: $0.00
A6: 45975 | B6: 45975 | C6: Saffron Supplement | D6: USD | E6: SP SAFFRON AUTO RESEARCH 05192025 GA | F6: auto | G6: United States | H6: loose-match | I6: - | J6: raw certified organic saffron capsules | K6: 1 | L6: 1 | M6: 1 | N6: $2.67 | O6: 2.67 | P6: 21.9 | Q6: 12.19 | R6: 8.2 | S6: 1 | T6: 1 | U6: 1 | V6: 1 | W6: 0 | X6: $21.90 | Y6: $0.00
A7: 45975 | B7: 45975 | C7: SP BROAD SEED | D7: USD | E7: SP MACA BROAD RESEARCH 22082024 HB | F7: MACA RESEARCH | G7: United States | H7: =+maca +root -> #NAME? | I7: BROAD | J7: wild yam and maca root | K7: 1 | L7: 1 | M7: 1 | N7: $4.35 | O7: 4.35 | P7: 24.94 | Q7: 17.44 | R7: 5.73 | S7: 1 | T7: 1 | U7: 1 | V7: 1 | W7: 0 | X7: $24.94 | Y7: $0.00
A8: 45974 | B8: 45975 | C8: SP TOS | D8: USD | E8: SP TOS MACA ASHWA KW RANK GA 04042024 | F8: MACA ASHWAGANDHA | G8: United States | H8: maca root ashwagandha | I8: PHRASE | J8: maca root and ashwagandha | K8: 17 | L8: 2 | M8: 0.117647 | N8: $2.68 | O8: 5.35 | P8: 24.94 | Q8: 21.45 | R8: 4.66 | S8: 1 | T8: 1 | U8: 0.5 | V8: 1 | W8: 0 | X8: $24.94 | Y8: $0.00
A9: 45974 | B9: 45974 | C9: Saffron Supplement | D9: USD | E9: SP SAFFRON EXACT SALES COMBO KW GA 05132025 | F9: Combo Exact | G9: United States | H9: saffron magnesium supplements | I9: EXACT | J9: saffron magnesium supplements | K9: 1 | L9: 1 | M9: 1 | N9: $2.97 | O9: 2.97 | P9: 43.8 | Q9: 6.78 | R9: 14.75 | S9: 1 | T9: 2 | U9: 1 | V9: 2 | W9: 0 | X9: $43.80 | Y9: $0.00
A10: 45973 | B10: 45973 | C10: Saffron Supplement | D10: USD | E10: SP SAFFRON EXACT SALES COMBO KW GA 05132025 | F10: Combo Exact | G10: United States | H10: ashwagandha magnesium | I10: EXACT | J10: ashwagandha and magnesium | K10: 16 | L10: 2 | M10: 0.125 | N10: $4.39 | O10: 8.77 | P10: 21.9 | Q10: 40.05 | R10: 2.5 | S10: 1 | T10: 1 | U10: 0.5 | V10: 1 | W10: 0 | X10: $21.90 | Y10: $0.00
A11: 45973 | B11: 45974 | C11: SP BROAD SEED | D11: USD | E11: SP AUTO MACA KW DISCOVERY GA | F11: AUTO | G11: United States | H11: close-match | I11: - | J11: ashwagandha maca root | K11: 17 | L11: 3 | M11: 0.176471 | N11: $3.60 | O11: 10.81 | P11: 24.94 | Q11: 43.34 | R11: 2.31 | S11: 1 | T11: 1 | U11: 0.333333 | V11: 1 | W11: 0 | X11: $24.94 | Y11: $0.00
A12: 45973 | B12: 45974 | C12: SP BROAD SEED | D12: USD | E12: SP MACA BROAD RESEARCH 22082024 HB | F12: MACA RESEARCH | G12: United States | H12: =+maca +root -> #NAME? | I12: BROAD | J12: maca root capsules | K12: 172 | L12: 2 | M12: 0.011628 | N12: $3.82 | O12: 7.64 | P12: 49.88 | Q12: 15.32 | R12: 6.53 | S12: 2 | T12: 2 | U12: 1 | V12: 2 | W12: 0 | X12: $49.88 | Y12: $0.00
A13: 45972 | B13: 45972 | C13: SP BROAD SEED | D13: USD | E13: SP MACA ROOT KW ASHWAGANDHA BROAD GA 29102022 | F13: ashwagandha | G13: United States | H13: ashwagandha | I13: BROAD | J13: ashwagandha for women | K13: 154 | L13: 2 | M13: 0.012987 | N13: $1.46 | O13: 2.92 | P13: 24.94 | Q13: 11.71 | R13: 8.54 | S13: 1 | T13: 1 | U13: 0.5 | V13: 1 | W13: 0 | X13: $24.94 | Y13: $0.00
A14: 45972 | B14: 45972 | C14: SP BROAD SEED | D14: USD | E14: SP MACA BROAD RESEARCH 22082024 HB | F14: MACA RESEARCH | G14: United States | H14: =+maca +root -> #NAME? | I14: BROAD | J14: maca root supplement | K14: 6 | L14: 1 | M14: 0.166667 | N14: $2.07 | O14: 2.07 | P14: 24.94 | Q14: 8.3 | R14: 12.05 | S14: 1 | T14: 1 | U14: 1 | V14: 1 | W14: 0 | X14: $24.94 | Y14: $0.00
A15: 45972 | B15: 45972 | C15: SP BROAD SEED | D15: USD | E15: SP MACA BROAD RESEARCH 22082024 HB | F15: MACA RESEARCH | G15: United States | H15: =+maca +root -> #NAME? | I15: BROAD | J15: magnesium maca root | K15: 2 | L15: 1 | M15: 0.5 | N15: $4.26 | O15: 4.26 | P15: 24.94 | Q15: 17.08 | R15: 5.85 | S15: 1 | T15: 1 | U15: 1 | V15: 1 | W15: 0 | X15: $24.94 | Y15: $0.00
A16: 45972 | B16: 45972 | C16: No Portfolio | D16: USD | E16: SP SAFFRON PHRASE SAFFRON ASHWA SALES GA 07182025 | F16: saffron ashwagandha | G16: United States | H16: saffron ashwagandha supplements | I16: PHRASE | J16: saffron and ashwagandha supplements | K16: 8 | L16: 2 | M16: 0.25 | N16: $3.41 | O16: 6.81 | P16: 21.9 | Q16: 31.1 | R16: 3.22 | S16: 1 | T16: 1 | U16: 0.5 | V16: 1 | W16: 0 | X16: $21.90 | Y16: $0.00
A17: 45972 | B17: 45976 | C17: No Portfolio | D17: USD | E17: SP SAFFRON PHRASE SAFFRON ASHWA SALES GA 07182025 | F17: saffron ashwagandha | G17: United States | H17: saffron ashwagandha | I17: PHRASE | J17: saffron ashwagandha | K17: 37 | L17: 4 | M17: 0.108108 | N17: $4.54 | O17: 18.14 | P17: 21.9 | Q17: 82.83 | R17: 1.21 | S17: 1 | T17: 1 | U17: 0.25 | V17: 1 | W17: 0 | X17: $21.90 | Y17: $0.00
A18: 45972 | B18: 45976 | C18: Saffron Supplement | D18: USD | E18: SP SAFFRON EXACT SALES COMBO KW GA 05132025 | F18: Combo Exact | G18: United States | H18: saffron ashwagandha supplements | I18: EXACT | J18: saffron ashwagandha supplements | K18: 12 | L18: 2 | M18: 0.166667 | N18: $3.04 | O18: 6.07 | P18: 21.9 | Q18: 27.72 | R18: 3.61 | S18: 1 | T18: 1 | U18: 0.5 | V18: 1 | W18: 0 | X18: $21.90 | Y18: $0.00
A19: 45971 | B19: 45976 | C19: SP BROAD SEED | D19: USD | E19: SP MACA ROOT KW ASHWAGANDHA BROAD GA 29102022 | F19: ashwagandha | G19: United States | H19: ashwagandha | I19: BROAD | J19: ashwagandha | K19: 319 | L19: 5 | M19: 0.015674 | N19: $2.68 | O19: 13.4 | P19: 74.82 | Q19: 17.91 | R19: 5.58 | S19: 3 | T19: 3 | U19: 0.6 | V19: 3 | W19: 0 | X19: $74.82 | Y19: $0.00
A20: 45971 | B20: 45971 | C20: SP BROAD SEED | D20: USD | E20: SP MACA ROOT KW ASHWAGANDHA BROAD GA 29102022 | F20: ashwagandha | G20: United States | H20: ashwagandha | I20: BROAD | J20: ashwagandha (root & leaf) | K20: 3 | L20: 1 | M20: 0.333333 | N20: $4.48 | O20: 4.48 | P20: 24.94 | Q20: 17.96 | R20: 5.57 | S20: 1 | T20: 1 | U20: 1 | V20: 1 | W20: 0 | X20: $24.94 | Y20: $0.00
A21: 45971 | B21: 45971 | C21: SP BROAD SEED | D21: USD | E21: SP MACA BROAD RESEARCH 22082024 HB | F21: MACA RESEARCH | G21: United States | H21: =+maca +root -> #NAME? | I21: BROAD | J21: ashwagandha root maca root l-carnitine | K21: 1 | L21: 1 | M21: 1 | N21: $4.35 | O21: 4.35 | P21: 24.94 | Q21: 17.44 | R21: 5.73 | S21: 1 | T21: 1 | U21: 1 | V21: 1 | W21: 0 | X21: $24.94 | Y21: $0.00
A22: 45971 | B22: 45974 | C22: SP BROAD SEED | D22: USD | E22: SP MACA BROAD RESEARCH 22082024 HB | F22: MACA RESEARCH | G22: United States | H22: =+maca +root -> #NAME? | I22: BROAD | J22: gaia herbs maca root | K22: 37 | L22: 2 | M22: 0.054054 | N22: $3.04 | O22: 6.08 | P22: 24.94 | Q22: 24.38 | R22: 4.1 | S22: 1 | T22: 1 | U22: 0.5 | V22: 1 | W22: 0 | X22: $24.94 | Y22: $0.00
A23: 45971 | B23: 45972 | C23: SP BROAD SEED | D23: USD | E23: SP AUTO MACA KW DISCOVERY GA | F23: AUTO | G23: United States | H23: close-match | I23: - | J23: maca capsules for men | K23: 16 | L23: 2 | M23: 0.125 | N23: $3.19 | O23: 6.38 | P23: 24.94 | Q23: 25.58 | R23: 3.91 | S23: 1 | T23: 1 | U23: 0.5 | V23: 1 | W23: 0 | X23: $24.94 | Y23: $0.00
A24: 45971 | B24: 45975 | C24: SP BROAD SEED | D24: USD | E24: SP AUTO MACA KW DISCOVERY GA | F24: AUTO | G24: United States | H24: loose-match | I24: - | J24: maca powder organic | K24: 104 | L24: 3 | M24: 0.028846 | N24: $2.38 | O24: 7.14 | P24: 49.88 | Q24: 14.31 | R24: 6.99 | S24: 2 | T24: 2 | U24: 0.666667 | V24: 2 | W24: 0 | X24: $49.88 | Y24: $0.00
A25: 45971 | B25: 45973 | C25: SP BROAD SEED | D25: USD | E25: SP AUTO MACA KW DISCOVERY GA | F25: AUTO | G25: United States | H25: close-match | I25: - | J25: maca root capsules | K25: 188 | L25: 3 | M25: 0.015957 | N25: $3.63 | O25: 10.9 | P25: 24.94 | Q25: 43.7 | R25: 2.29 | S25: 1 | T25: 1 | U25: 0.333333 | V25: 1 | W25: 0 | X25: $24.94 | Y25: $0.00
A26: 45971 | B26: 45972 | C26: SP BROAD SEED | D26: USD | E26: SP AUTO MACA KW DISCOVERY GA | F26: AUTO | G26: United States | H26: close-match | I26: - | J26: maca root capsules for men | K26: 1354 | L26: 3 | M26: 0.002216 | N26: $2.73 | O26: 8.18 | P26: 74.82 | Q26: 10.93 | R26: 9.15 | S26: 2 | T26: 3 | U26: 0.666667 | V26: 3 | W26: 0 | X26: $74.82 | Y26: $0.00
A27: 45971 | B27: 45971 | C27: SP BROAD SEED | D27: USD | E27: SP AUTO MACA KW DISCOVERY GA | F27: AUTO | G27: United States | H27: loose-match | I27: - | J27: women's energy enhancer | K27: 1 | L27: 1 | M27: 1 | N27: $3.72 | O27: 3.72 | P27: 24.94 | Q27: 14.92 | R27: 6.7 | S27: 1 | T27: 1 | U27: 1 | V27: 1 | W27: 0 | X27: $24.94 | Y27: $0.00
A28: 45970 | B28: 45976 | C28: Rank | D28: USD | E28: SP TOS KW ASHWGANDHA GA RANK 07082024 | F28: ashwagandha | G28: United States | H28: ashwagandha | I28: EXACT | J28: ashwagandha | K28: 3631 | L28: 12 | M28: 0.003305 | N28: $2.91 | O28: 34.88 | P28: 74.82 | Q28: 46.62 | R28: 2.15 | S28: 3 | T28: 3 | U28: 0.25 | V28: 3 | W28: 0 | X28: $74.82 | Y28: $0.00
A29: 45970 | B29: 45970 | C29: No Portfolio | D29: USD | E29: SP EXACT BRANDED SEARCH | F29: Branded search | G29: United States | H29: circle of nature | I29: PHRASE | J29: circle of nature saffron | K29: 2 | L29: 1 | M29: 0.5 | N29: $2.57 | O29: 2.57 | P29: 21.9 | Q29: 11.74 | R29: 8.52 | S29: 1 | T29: 1 | U29: 1 | V29: 1 | W29: 0 | X29: $21.90 | Y29: $0.00
A30: 45970 | B30: 45975 | C30: SP TOS | D30: USD | E30: SP TOS MACA ASHWA KW RANK GA 04042024 | F30: MACA ASHWAGANDHA | G30: United States | H30: maca root ashwagandha | I30: PHRASE | J30: concentrated maca root and ashwagandha | K30: 15 | L30: 4 | M30: 0.266667 | N30: $3.33 | O30: 13.31 | P30: 24.94 | Q30: 53.37 | R30: 1.87 | S30: 1 | T30: 1 | U30: 0.25 | V30: 1 | W30: 0 | X30: $24.94 | Y30: $0.00
A31: 45970 | B31: 45970 | C31: SP BROAD SEED | D31: USD | E31: SP AUTO MACA KW DISCOVERY GA | F31: AUTO | G31: United States | H31: loose-match | I31: - | J31: maca mix capsules | K31: 3 | L31: 1 | M31: 0.333333 | N31: $3.79 | O31: 3.79 | P31: 24.94 | Q31: 15.2 | R31: 6.58 | S31: 1 | T31: 1 | U31: 1 | V31: 1 | W31: 0 | X31: $24.94 | Y31: $0.00
A32: 45970 | B32: 45976 | C32: Rank | D32: USD | E32: MACA ROOT TOS EXACT CAMPAIGN 27042022 RANK | F32: MACA EXACT TEST CAMPAIGN | G32: United States | H32: maca root | I32: EXACT | J32: maca root | K32: 1193 | L32: 46 | M32: 0.038558 | N32: $3.10 | O32: 142.49 | P32: 174.58 | Q32: 81.62 | R32: 1.23 | S32: 6 | T32: 7 | U32: 0.130435 | V32: 7 | W32: 0 | X32: $174.58 | Y32: $0.00
A33: 45970 | B33: 45974 | C33: SP BROAD SEED | D33: USD | E33: SP AUTO MACA KW DISCOVERY GA | F33: AUTO | G33: United States | H33: close-match | I33: - | J33: maca root ashwagandha | K33: 89 | L33: 5 | M33: 0.05618 | N33: $3.65 | O33: 18.25 | P33: 24.94 | Q33: 73.18 | R33: 1.37 | S33: 1 | T33: 1 | U33: 0.2 | V33: 1 | W33: 0 | X33: $24.94 | Y33: $0.00
A34: 45970 | B34: 45972 | C34: SP BROAD SEED | D34: USD | E34: SP AUTO MACA KW DISCOVERY GA | F34: AUTO | G34: United States | H34: loose-match | I34: - | J34: maca root ashwagandha drops | K34: 2 | L34: 2 | M34: 1 | N34: $2.63 | O34: 5.26 | P34: 24.94 | Q34: 21.09 | R34: 4.74 | S34: 1 | T34: 1 | U34: 0.5 | V34: 1 | W34: 0 | X34: $24.94 | Y34: $0.00
A35: 45970 | B35: 45975 | C35: SP BROAD SEED | D35: USD | E35: SP MACA BROAD RESEARCH 22082024 HB | F35: MACA RESEARCH | G35: United States | H35: =+maca +root -> #NAME? | I35: BROAD | J35: maca root for menopause | K35: 23 | L35: 3 | M35: 0.130435 | N35: $3.27 | O35: 9.81 | P35: 24.94 | Q35: 39.33 | R35: 2.54 | S35: 1 | T35: 1 | U35: 0.333333 | V35: 1 | W35: 0 | X35: $24.94 | Y35: $0.00
A36: 45970 | B36: 45970 | C36: SP BROAD SEED | D36: USD | E36: SP MACA BROAD RESEARCH 22082024 HB | F36: MACA RESEARCH | G36: United States | H36: =+maca +root -> #NAME? | I36: BROAD | J36: nature's way maca root capsules | K36: 5 | L36: 2 | M36: 0.4 | N36: $3.98 | O36: 7.96 | P36: 24.94 | Q36: 31.92 | R36: 3.13 | S36: 1 | T36: 1 | U36: 0.5 | V36: 1 | W36: 0 | X36: $24.94 | Y36: $0.00
A37: 45970 | B37: 45974 | C37: Saffron Supplement | D37: USD | E37: SP SAFFRON EXACT SALES COMBO KW GA 05132025 | F37: Combo Exact | G37: United States | H37: saffron ashwagandha supplements | I37: EXACT | J37: saffron and ashwagandha supplements | K37: 44 | L37: 5 | M37: 0.113636 | N37: $4.97 | O37: 24.85 | P37: 21.9 | Q37: 113.47 | R37: 0.88 | S37: 1 | T37: 1 | U37: 0.2 | V37: 1 | W37: 0 | X37: $21.90 | Y37: $0.00
A38: 45969 | B38: 45969 | C38: Saffron Supplement | D38: USD | E38: SP SAFFRON AUTO RESEARCH 05192025 GA | F38: auto | G38: United States | H38: loose-match | I38: - | J38: ashwagandha and saffron supplements | K38: 1 | L38: 1 | M38: 1 | N38: $3.00 | O38: 3 | P38: 21.9 | Q38: 13.7 | R38: 7.3 | S38: 1 | T38: 1 | U38: 1 | V38: 1 | W38: 0 | X38: $21.90 | Y38: $0.00
A39: 45969 | B39: 45969 | C39: SP BROAD SEED | D39: USD | E39: SP AUTO MACA KW DISCOVERY GA | F39: AUTO | G39: United States | H39: loose-match | I39: - | J39: maca root | K39: 0 | L39: 0 | O39: 0 | P39: 24.94 | Q39: 0 | S39: 1 | T39: 1 | V39: 1 | W39: 0 | X39: $24.94 | Y39: $0.00
A40: 45969 | B40: 45969 | C40: SP BROAD SEED | D40: USD | E40: SP MACA BROAD RESEARCH 22082024 HB | F40: MACA RESEARCH | G40: United States | H40: =+maca +root -> #NAME? | I40: BROAD | J40: shawanda and maca root | K40: 2 | L40: 1 | M40: 0.5 | N40: $2.73 | O40: 2.73 | P40: 24.94 | Q40: 10.95 | R40: 9.14 | S40: 1 | T40: 1 | U40: 1 | V40: 1 | W40: 0 | X40: $24.94 | Y40: $0.00
...

Sheet CamparisionReport
B1: 5 week comp. | C1: November 2nd Week | H1: November 1st Week | M1: October 4th Week | R1: October 3rd Week | W1: October 2nd Week | AB1: October 1st Week | AG1: Sep 5th Week | AL1: Sep 4th Week | AQ1: Sep 3rd Week | AV1: Sep 2nd Week | BA1: Sep 1st Week | BF1: Aug Week 5 | BK1: Aug Week 4 | BP1: Aug Week 3 | BU1: Aug Week 2 | BZ1: Aug Week 1
A2: Customer Search Term | B2: Performance | C2: Clicks | D2: Imp | E2: Spend | F2: Sales | G2: Acos | H2: Clicks | I2: Imp | J2: Spend | K2: Sales | L2: Acos | M2: Clicks | N2: Imp | O2: Spend | P2: Sales | Q2: Acos | R2: Clicks | S2: Imp | T2: Spend | U2: Sales | V2: Acos | W2: Clicks | X2: Imp | Y2: Spend | Z2: Sales | AA2: Acos | AB2: Clicks | AC2: Imp | AD2: Spend | AE2: Sales | AF2: Acos | AG2: Clicks | AH2: Imp | AI2: Spend | AJ2: Sales | AK2: Acos | AL2: Clicks | AM2: Imp | AN2: Spend | AO2: Sales | AP2: Acos | AQ2: Clicks | AR2: Imp | AS2: Spend | AT2: Sales | AU2: Acos | AV2: Clicks | AW2: Imp | AX2: Spend | AY2: Sales | AZ2: Acos | BA2: Clicks | BB2: Imp | BC2: Spend | BD2: Sales | BE2: Acos | BF2: Clicks | BG2: Imp | BH2: Spend | BI2: Sales | BJ2: Acos | BK2: Clicks | BL2: Imp | BM2: Spend | BN2: Sales | BO2: Acos | BP2: Clicks | BQ2: Imp | BR2: Spend | BS2: Sales | BT2: Acos | BU2: Clicks | BV2: Imp | BW2: Spend | BX2: Sales | BY2: Acos | BZ2: Clicks | CA2: Imp | CB2: Spend | CC2: Sales | CD2: Acos
A3: maca root | B3: =IF( (E3+J3+O3+T3+Y3)=0, "NO TRAFFIC", IF( (F3+K3+P3+U3+Z3)=0, "CLICKS NO SALES", IF( ((E3+J3+O3+T3+Y3)/(F3+K3+P3+U3+Z3)*100)<=35, "WINNER", "HIGH ACOS" ) ) ) -> HIGH ACOS | C3: =SUMIFS('9NovTo15Nov'!$L:$L, '9NovTo15Nov'!$J:$J, $A3) -> 46 | D3: =SUMIFS('9NovTo15Nov'!$K:$K, '9NovTo15Nov'!$J:$J, $A3) -> 1193 | E3: =SUMIFS('9NovTo15Nov'!$O:$O, '9NovTo15Nov'!$J:$J, $A3) -> 142.49 | F3: =SUMIFS('9NovTo15Nov'!$P:$P, '9NovTo15Nov'!$J:$J, $A3) -> 174.58 | G3: =IF(F3=0, 0, E3/F3*100) -> 81.618742 | H3: =SUMIFS('2NovTo8Nov'!$L:$L, '2NovTo8Nov'!$J:$J, $A3) -> 52 | I3: =SUMIFS('2NovTo8Nov'!$K:$K, '2NovTo8Nov'!$J:$J, $A3) -> 1957 | J3: =SUMIFS('2NovTo8Nov'!$O:$O, '2NovTo8Nov'!$J:$J, $A3) -> 156.45 | K3: =SUMIFS('2NovTo8Nov'!$P:$P, '2NovTo8Nov'!$J:$J, $A3) -> 324.22 | L3: =IF(K3=0, 0, J3/K3*100) -> 48.254272 | M3: =SUMIFS('26OctTo1Nov'!$L:$L, '26OctTo1Nov'!$J:$J, $A3) -> 67 | N3: =SUMIFS('26OctTo1Nov'!$K:$K, '26OctTo1Nov'!$J:$J, $A3) -> 2725 | O3: =SUMIFS('26OctTo1Nov'!$O:$O, '26OctTo1Nov'!$J:$J, $A3) -> 208.67 | P3: =SUMIFS('26OctTo1Nov'!$P:$P, '26OctTo1Nov'!$J:$J, $A3) -> 498.8 | Q3: =IF(P3=0, 0, O3/P3*100) -> 41.834403 | R3: =SUMIFS('19OctTo25Oct'!$L:$L, '19OctTo25Oct'!$J:$J, $A3) -> 53 | S3: =SUMIFS('19OctTo25Oct'!$K:$K, '19OctTo25Oct'!$J:$J, $A3) -> 4522 | T3: =SUMIFS('19OctTo25Oct'!$O:$O, '19OctTo25Oct'!$J:$J, $A3) -> 191.67 | U3: =SUMIFS('19OctTo25Oct'!$P:$P, '19OctTo25Oct'!$J:$J, $A3) -> 199.52 | V3: =IF(U3=0, 0, T3/U3*100) -> 96.065557 | W3: =SUMIFS('12OctTo18Oct'!$L:$L, '12OctTo18Oct'!$J:$J, $A3) -> 71 | X3: =SUMIFS('12OctTo18Oct'!$K:$K, '12OctTo18Oct'!$J:$J, $A3) -> 4225 | Y3: =SUMIFS('12OctTo18Oct'!$O:$O, '12OctTo18Oct'!$J:$J, $A3) -> 209.71 | Z3: =SUMIFS('12OctTo18Oct'!$P:$P, '12OctTo18Oct'!$J:$J, $A3) -> 299.28 | AA3: =IF(Z3=0, 0, Y3/Z3*100) -> 70.071505 | AB3: =SUMIFS('5OctTo11Oct'!$L:$L, '5OctTo11Oct'!$J:$J, $A3) -> 62 | AC3: =SUMIFS('5OctTo11Oct'!$K:$K, '5OctTo11Oct'!$J:$J, $A3) -> 3370 | AD3: =SUMIFS('5OctTo11Oct'!$O:$O, '5OctTo11Oct'!$J:$J, $A3) -> 194.77 | AE3: =SUMIFS('5OctTo11Oct'!$P:$P, '5OctTo11Oct'!$J:$J, $A3) -> 244.4 | AF3: =IF(AE3=0, 0, AD3/AE3*100) -> 79.693126 | AG3: =SUMIFS('28SepTo4Oct'!$L:$L, '28SepTo4Oct'!$J:$J, $A3) -> 55 | AH3: =SUMIFS('28SepTo4Oct'!$K:$K, '28SepTo4Oct'!$J:$J, $A3) -> 5597 | AI3: =SUMIFS('28SepTo4Oct'!$O:$O, '28SepTo4Oct'!$J:$J, $A3) -> 179.96 | AJ3: =SUMIFS('28SepTo4Oct'!$P:$P, '28SepTo4Oct'!$J:$J, $A3) -> 189.64 | AK3: =IF(AJ3=0, 0, AI3/AJ3*100) -> 94.895592 | AL3: =SUMIFS('21SepTo27Sep'!$L:$L, '21SepTo27Sep'!$J:$J, $A3) -> 58 | AM3: =SUMIFS('21SepTo27Sep'!$K:$K, '21SepTo27Sep'!$J:$J, $A3) -> 4915 | AN3: =SUMIFS('21SepTo27Sep'!$O:$O, '21SepTo27Sep'!$J:$J, $A3) -> 180.03 | AO3: =SUMIFS('21SepTo27Sep'!$P:$P, '21SepTo27Sep'!$J:$J, $A3) -> 122.26 | AP3: =IF(AO3=0, 0, AN3/AO3*100) -> 147.25176 | AQ3: =SUMIFS('14SepTo20Sep'!$L:$L, '14SepTo20Sep'!$J:$J, $A3) -> 75 | AR3: =SUMIFS('14SepTo20Sep'!$K:$K, '14SepTo20Sep'!$J:$J, $A3) -> 5195 | AS3: =SUMIFS('14SepTo20Sep'!$O:$O, '14SepTo20Sep'!$J:$J, $A3) -> 239.51 | AT3: =SUMIFS('14SepTo20Sep'!$P:$P, '14SepTo20Sep'!$J:$J, $A3) -> 199.52 | AU3: =IF(AT3=0, 0, AS3/AT3*100) -> 120.0431 | AV3: =SUMIFS('7SepTo13Sep'!$L:$L, '7SepTo13Sep'!$J:$J, $A3) -> 66 | AW3: =SUMIFS('7SepTo13Sep'!$K:$K, '7SepTo13Sep'!$J:$J, $A3) -> 5173 | AX3: =SUMIFS('7SepTo13Sep'!$O:$O, '7SepTo13Sep'!$J:$J, $A3) -> 194.16 | AY3: =SUMIFS('7SepTo13Sep'!$P:$P, '7SepTo13Sep'!$J:$J, $A3) -> 374.1 | AZ3: =IF(AY3=0, 0, AX3/AY3*100) -> 51.900561 | BA3: =SUMIFS('31AugTo6Sep'!$L:$L, '31AugTo6Sep'!$J:$J, $A3) -> 76 | BB3: =SUMIFS('31AugTo6Sep'!$K:$K, '31AugTo6Sep'!$J:$J, $A3) -> 4656 | BC3: =SUMIFS('31AugTo6Sep'!$O:$O, '31AugTo6Sep'!$J:$J, $A3) -> 209.44 | BD3: =SUMIFS('31AugTo6Sep'!$P:$P, '31AugTo6Sep'!$J:$J, $A3) -> 361.78 | BE3: =IF(BD3=0, 0, BC3/BD3*100) -> 57.891536 | BF3: =SUMIFS('24AugTo29Aug'!$L:$L, '24AugTo29Aug'!$J:$J, $A3) -> 24 | BG3: =SUMIFS('24AugTo29Aug'!$K:$K, '24AugTo29Aug'!$J:$J, $A3) -> 1930 | BH3: =SUMIFS('24AugTo29Aug'!$O:$O, '24AugTo29Aug'!$J:$J, $A3) -> 70.94 | BI3: =SUMIFS('24AugTo29Aug'!$P:$P, '24AugTo29Aug'!$J:$J, $A3) -> 99.76 | BJ3: =IF(BI3=0, 0, BH3/BI3*100) -> 71.110666 | BK3: =SUMIFS('17AugTo21Aug'!$L:$L, '17AugTo21Aug'!$J:$J, $A3) -> 48 | BL3: =SUMIFS('17AugTo21Aug'!$K:$K, '17AugTo21Aug'!$J:$J, $A3) -> 3821 | BM3: =SUMIFS('17AugTo21Aug'!$O:$O, '17AugTo21Aug'!$J:$J, $A3) -> 126.9 | BN3: =SUMIFS('17AugTo21Aug'!$P:$P, '17AugTo21Aug'!$J:$J, $A3) -> 149.64 | BO3: =IF(BN3=0, 0, BM3/BN3*100) -> 84.803528 | BP3: =SUMIFS('10AugTo16Aug'!$L:$L, '10AugTo16Aug'!$J:$J, $A3) -> 107 | BQ3: =SUMIFS('10AugTo16Aug'!$K:$K, '10AugTo16Aug'!$J:$J, $A3) -> 6034 | BR3: =SUMIFS('10AugTo16Aug'!$O:$O, '10AugTo16Aug'!$J:$J, $A3) -> 265.68 | BS3: =SUMIFS('10AugTo16Aug'!$P:$P, '10AugTo16Aug'!$J:$J, $A3) -> 374.1 | BT3: =IF(BS3=0, 0, BR3/BS3*100) -> 71.018444 | BU3: =SUMIFS('3AugTo9Aug'!$L:$L, '3AugTo9Aug'!$J:$J, $A3) -> 94 | BV3: =SUMIFS('3AugTo9Aug'!$K:$K, '3AugTo9Aug'!$J:$J, $A3) -> 8313 | BW3: =SUMIFS('3AugTo9Aug'!$O:$O, '3AugTo9Aug'!$J:$J, $A3) -> 238.01 | BX3: =SUMIFS('3AugTo9Aug'!$P:$P, '3AugTo9Aug'!$J:$J, $A3) -> 448.92 | BY3: =IF(BX3=0, 0, BW3/BX3*100) -> 53.018355 | BZ3: =SUMIFS('27JulyTo2Aug'!$L:$L, '27JulyTo2Aug'!$J:$J, $A3) -> 72 | CA3: =SUMIFS('27JulyTo2Aug'!$K:$K, '27JulyTo2Aug'!$J:$J, $A3) -> 4617 | CB3: =SUMIFS('27JulyTo2Aug'!$O:$O, '27JulyTo2Aug'!$J:$J, $A3) -> 175.8 | CC3: =SUMIFS('27JulyTo2Aug'!$P:$P, '27JulyTo2Aug'!$J:$J, $A3) -> 296.84 | CD3: =IF(CC3=0, 0, CB3/CC3*100) -> 59.223824
A4: maca root ashwagandha | B4: =IF( (E4+J4+O4+T4+Y4)=0, "NO TRAFFIC", IF( (F4+K4+P4+U4+Z4)=0, "CLICKS NO SALES", IF( ((E4+J4+O4+T4+Y4)/(F4+K4+P4+U4+Z4)*100)<=35, "WINNER", "HIGH ACOS" ) ) ) -> HIGH ACOS | C4: =SUMIFS('9NovTo15Nov'!$L:$L, '9NovTo15Nov'!$J:$J, $A4) -> 5 | D4: =SUMIFS('9NovTo15Nov'!$K:$K, '9NovTo15Nov'!$J:$J, $A4) -> 89 | E4: =SUMIFS('9NovTo15Nov'!$O:$O, '9NovTo15Nov'!$J:$J, $A4) -> 18.25 | F4: =SUMIFS('9NovTo15Nov'!$P:$P, '9NovTo15Nov'!$J:$J, $A4) -> 24.94 | G4: =IF(F4=0, 0, E4/F4*100) -> 73.175621 | H4: =SUMIFS('2NovTo8Nov'!$L:$L, '2NovTo8Nov'!$J:$J, $A4) -> 11 | I4: =SUMIFS('2NovTo8Nov'!$K:$K, '2NovTo8Nov'!$J:$J, $A4) -> 129 | J4: =SUMIFS('2NovTo8Nov'!$O:$O, '2NovTo8Nov'!$J:$J, $A4) -> 34.2 | K4: =SUMIFS('2NovTo8Nov'!$P:$P, '2NovTo8Nov'!$J:$J, $A4) -> 74.82 | L4: =IF(K4=0, 0, J4/K4*100) -> 45.709703 | M4: =SUMIFS('26OctTo1Nov'!$L:$L, '26OctTo1Nov'!$J:$J, $A4) -> 21 | N4: =SUMIFS('26OctTo1Nov'!$K:$K, '26OctTo1Nov'!$J:$J, $A4) -> 201 | O4: =SUMIFS('26OctTo1Nov'!$O:$O, '26OctTo1Nov'!$J:$J, $A4) -> 72.44 | P4: =SUMIFS('26OctTo1Nov'!$P:$P, '26OctTo1Nov'!$J:$J, $A4) -> 124.7 | Q4: =IF(P4=0, 0, O4/P4*100) -> 58.091419 | R4: =SUMIFS('19OctTo25Oct'!$L:$L, '19OctTo25Oct'!$J:$J, $A4) -> 13 | S4: =SUMIFS('19OctTo25Oct'!$K:$K, '19OctTo25Oct'!$J:$J, $A4) -> 193 | T4: =SUMIFS('19OctTo25Oct'!$O:$O, '19OctTo25Oct'!$J:$J, $A4) -> 40.01 | U4: =SUMIFS('19OctTo25Oct'!$P:$P, '19OctTo25Oct'!$J:$J, $A4) -> 74.82 | V4: =IF(U4=0, 0, T4/U4*100) -> 53.475007 | W4: =SUMIFS('12OctTo18Oct'!$L:$L, '12OctTo18Oct'!$J:$J, $A4) -> 15 | X4: =SUMIFS('12OctTo18Oct'!$K:$K, '12OctTo18Oct'!$J:$J, $A4) -> 344 | Y4: =SUMIFS('12OctTo18Oct'!$O:$O, '12OctTo18Oct'!$J:$J, $A4) -> 42.66 | Z4: =SUMIFS('12OctTo18Oct'!$P:$P, '12OctTo18Oct'!$J:$J, $A4) -> 99.76 | AA4: =IF(Z4=0, 0, Y4/Z4*100) -> 42.76263 | AB4: =SUMIFS('5OctTo11Oct'!$L:$L, '5OctTo11Oct'!$J:$J, $A4) -> 17 | AC4: =SUMIFS('5OctTo11Oct'!$K:$K, '5OctTo11Oct'!$J:$J, $A4) -> 416 | AD4: =SUMIFS('5OctTo11Oct'!$O:$O, '5OctTo11Oct'!$J:$J, $A4) -> 50.49 | AE4: =SUMIFS('5OctTo11Oct'!$P:$P, '5OctTo11Oct'!$J:$J, $A4) -> 124.7 | AF4: =IF(AE4=0, 0, AD4/AE4*100) -> 40.489174 | AG4: =SUMIFS('28SepTo4Oct'!$L:$L, '28SepTo4Oct'!$J:$J, $A4) -> 14 | AH4: =SUMIFS('28SepTo4Oct'!$K:$K, '28SepTo4Oct'!$J:$J, $A4) -> 335 | AI4: =SUMIFS('28SepTo4Oct'!$O:$O, '28SepTo4Oct'!$J:$J, $A4) -> 44.19 | AJ4: =SUMIFS('28SepTo4Oct'!$P:$P, '28SepTo4Oct'!$J:$J, $A4) -> 74.82 | AK4: =IF(AJ4=0, 0, AI4/AJ4*100) -> 59.061748 | AL4: =SUMIFS('21SepTo27Sep'!$L:$L, '21SepTo27Sep'!$J:$J, $A4) -> 21 | AM4: =SUMIFS('21SepTo27Sep'!$K:$K, '21SepTo27Sep'!$J:$J, $A4) -> 603 | AN4: =SUMIFS('21SepTo27Sep'!$O:$O, '21SepTo27Sep'!$J:$J, $A4) -> 61.69 | AO4: =SUMIFS('21SepTo27Sep'!$P:$P, '21SepTo27Sep'!$J:$J, $A4) -> 172.14 | AP4: =IF(AO4=0, 0, AN4/AO4*100) -> 35.837109 | AQ4: =SUMIFS('14SepTo20Sep'!$L:$L, '14SepTo20Sep'!$J:$J, $A4) -> 12 | AR4: =SUMIFS('14SepTo20Sep'!$K:$K, '14SepTo20Sep'!$J:$J, $A4) -> 102 | AS4: =SUMIFS('14SepTo20Sep'!$O:$O, '14SepTo20Sep'!$J:$J, $A4) -> 38.55 | AT4: =SUMIFS('14SepTo20Sep'!$P:$P, '14SepTo20Sep'!$J:$J, $A4) -> 24.94 | AU4: =IF(AT4=0, 0, AS4/AT4*100) -> 154.57097 | AV4: =SUMIFS('7SepTo13Sep'!$L:$L, '7SepTo13Sep'!$J:$J, $A4) -> 16 | AW4: =SUMIFS('7SepTo13Sep'!$K:$K, '7SepTo13Sep'!$J:$J, $A4) -> 241 | AX4: =SUMIFS('7SepTo13Sep'!$O:$O, '7SepTo13Sep'!$J:$J, $A4) -> 54.51 | AY4: =SUMIFS('7SepTo13Sep'!$P:$P, '7SepTo13Sep'!$J:$J, $A4) -> 174.58 | AZ4: =IF(AY4=0, 0, AX4/AY4*100) -> 31.223508 | BA4: =SUMIFS('31AugTo6Sep'!$L:$L, '31AugTo6Sep'!$J:$J, $A4) -> 2 | BB4: =SUMIFS('31AugTo6Sep'!$K:$K, '31AugTo6Sep'!$J:$J, $A4) -> 6 | BC4: =SUMIFS('31AugTo6Sep'!$O:$O, '31AugTo6Sep'!$J:$J, $A4) -> 7.09 | BD4: =SUMIFS('31AugTo6Sep'!$P:$P, '31AugTo6Sep'!$J:$J, $A4) -> 24.94 | BE4: =IF(BD4=0, 0, BC4/BD4*100) -> 28.428228 | BF4: =SUMIFS('24AugTo29Aug'!$L:$L, '24AugTo29Aug'!$J:$J, $A4) -> 16 | BG4: =SUMIFS('24AugTo29Aug'!$K:$K, '24AugTo29Aug'!$J:$J, $A4) -> 1552 | BH4: =SUMIFS('24AugTo29Aug'!$O:$O, '24AugTo29Aug'!$J:$J, $A4) -> 47.26 | BI4: =SUMIFS('24AugTo29Aug'!$P:$P, '24AugTo29Aug'!$J:$J, $A4) -> 74.82 | BJ4: =IF(BI4=0, 0, BH4/BI4*100) -> 63.164929 | BK4: =SUMIFS('17AugTo21Aug'!$L:$L, '17AugTo21Aug'!$J:$J, $A4) -> 5 | BL4: =SUMIFS('17AugTo21Aug'!$K:$K, '17AugTo21Aug'!$J:$J, $A4) -> 214 | BM4: =SUMIFS('17AugTo21Aug'!$O:$O, '17AugTo21Aug'!$J:$J, $A4) -> 13.79 | BN4: =SUMIFS('17AugTo21Aug'!$P:$P, '17AugTo21Aug'!$J:$J, $A4) -> 97.32 | BO4: =IF(BN4=0, 0, BM4/BN4*100) -> 14.169749 | BP4: =SUMIFS('10AugTo16Aug'!$L:$L, '10AugTo16Aug'!$J:$J, $A4) -> 22 | BQ4: =SUMIFS('10AugTo16Aug'!$K:$K, '10AugTo16Aug'!$J:$J, $A4) -> 702 | BR4: =SUMIFS('10AugTo16Aug'!$O:$O, '10AugTo16Aug'!$J:$J, $A4) -> 69.75 | BS4: =SUMIFS('10AugTo16Aug'!$P:$P, '10AugTo16Aug'!$J:$J, $A4) -> 99.76 | BT4: =IF(BS4=0, 0, BR4/BS4*100) -> 69.917803 | BU4: =SUMIFS('3AugTo9Aug'!$L:$L, '3AugTo9Aug'!$J:$J, $A4) -> 9 | BV4: =SUMIFS('3AugTo9Aug'!$K:$K, '3AugTo9Aug'!$J:$J, $A4) -> 242 | BW4: =SUMIFS('3AugTo9Aug'!$O:$O, '3AugTo9Aug'!$J:$J, $A4) -> 31.18 | BX4: =SUMIFS('3AugTo9Aug'!$P:$P, '3AugTo9Aug'!$J:$J, $A4) -> 99.76 | BY4: =IF(BX4=0, 0, BW4/BX4*100) -> 31.255012 | BZ4: =SUMIFS('27JulyTo2Aug'!$L:$L, '27JulyTo2Aug'!$J:$J, $A4) -> 15 | CA4: =SUMIFS('27JulyTo2Aug'!$K:$K, '27JulyTo2Aug'!$J:$J, $A4) -> 387 | CB4: =SUMIFS('27JulyTo2Aug'!$O:$O, '27JulyTo2Aug'!$J:$J, $A4) -> 51.23 | CC4: =SUMIFS('27JulyTo2Aug'!$P:$P, '27JulyTo2Aug'!$J:$J, $A4) -> 74.82 | CD4: =IF(CC4=0, 0, CB4/CC4*100) -> 68.470997
A5: ashwagandha | B5: =IF( (E5+J5+O5+T5+Y5)=0, "NO TRAFFIC", IF( (F5+K5+P5+U5+Z5)=0, "CLICKS NO SALES", IF( ((E5+J5+O5+T5+Y5)/(F5+K5+P5+U5+Z5)*100)<=35, "WINNER", "HIGH ACOS" ) ) ) -> HIGH ACOS | C5: =SUMIFS('9NovTo15Nov'!$L:$L, '9NovTo15Nov'!$J:$J, $A5) -> 17 | D5: =SUMIFS('9NovTo15Nov'!$K:$K, '9NovTo15Nov'!$J:$J, $A5) -> 3950 | E5: =SUMIFS('9NovTo15Nov'!$O:$O, '9NovTo15Nov'!$J:$J, $A5) -> 48.28 | F5: =SUMIFS('9NovTo15Nov'!$P:$P, '9NovTo15Nov'!$J:$J, $A5) -> 149.64 | G5: =IF(F5=0, 0, E5/F5*100) -> 32.264101 | H5: =SUMIFS('2NovTo8Nov'!$L:$L, '2NovTo8Nov'!$J:$J, $A5) -> 10 | I5: =SUMIFS('2NovTo8Nov'!$K:$K, '2NovTo8Nov'!$J:$J, $A5) -> 2756 | J5: =SUMIFS('2NovTo8Nov'!$O:$O, '2NovTo8Nov'!$J:$J, $A5) -> 21.94 | K5: =SUMIFS('2NovTo8Nov'!$P:$P, '2NovTo8Nov'!$J:$J, $A5) -> 24.94 | L5: =IF(K5=0, 0, J5/K5*100) -> 87.971131 | M5: =SUMIFS('26OctTo1Nov'!$L:$L, '26OctTo1Nov'!$J:$J, $A5) -> 21 | N5: =SUMIFS('26OctTo1Nov'!$K:$K, '26OctTo1Nov'!$J:$J, $A5) -> 4109 | O5: =SUMIFS('26OctTo1Nov'!$O:$O, '26OctTo1Nov'!$J:$J, $A5) -> 56.92 | P5: =SUMIFS('26OctTo1Nov'!$P:$P, '26OctTo1Nov'!$J:$J, $A5) -> 24.94 | Q5: =IF(P5=0, 0, O5/P5*100) -> 228.22775 | R5: =SUMIFS('19OctTo25Oct'!$L:$L, '19OctTo25Oct'!$J:$J, $A5) -> 27 | S5: =SUMIFS('19OctTo25Oct'!$K:$K, '19OctTo25Oct'!$J:$J, $A5) -> 7472 | T5: =SUMIFS('19OctTo25Oct'!$O:$O, '19OctTo25Oct'!$J:$J, $A5) -> 75.11 | U5: =SUMIFS('19OctTo25Oct'!$P:$P, '19OctTo25Oct'!$J:$J, $A5) -> 174.58 | V5: =IF(U5=0, 0, T5/U5*100) -> 43.023256 | W5: =SUMIFS('12OctTo18Oct'!$L:$L, '12OctTo18Oct'!$J:$J, $A5) -> 31 | X5: =SUMIFS('12OctTo18Oct'!$K:$K, '12OctTo18Oct'!$J:$J, $A5) -> 3930 | Y5: =SUMIFS('12OctTo18Oct'!$O:$O, '12OctTo18Oct'!$J:$J, $A5) -> 83.01 | Z5: =SUMIFS('12OctTo18Oct'!$P:$P, '12OctTo18Oct'!$J:$J, $A5) -> 249.4 | AA5: =IF(Z5=0, 0, Y5/Z5*100) -> 33.283881 | AB5: =SUMIFS('5OctTo11Oct'!$L:$L, '5OctTo11Oct'!$J:$J, $A5) -> 11 | AC5: =SUMIFS('5OctTo11Oct'!$K:$K, '5OctTo11Oct'!$J:$J, $A5) -> 545 | AD5: =SUMIFS('5OctTo11Oct'!$O:$O, '5OctTo11Oct'!$J:$J, $A5) -> 36.65 | AE5: =SUMIFS('5OctTo11Oct'!$P:$P, '5OctTo11Oct'!$J:$J, $A5) -> 74.82 | AF5: =IF(AE5=0, 0, AD5/AE5*100) -> 48.984229 | AG5: =SUMIFS('28SepTo4Oct'!$L:$L, '28SepTo4Oct'!$J:$J, $A5) -> 5 | AH5: =SUMIFS('28SepTo4Oct'!$K:$K, '28SepTo4Oct'!$J:$J, $A5) -> 253 | AI5: =SUMIFS('28SepTo4Oct'!$O:$O, '28SepTo4Oct'!$J:$J, $A5) -> 16.91 | AJ5: =SUMIFS('28SepTo4Oct'!$P:$P, '28SepTo4Oct'!$J:$J, $A5) -> 24.94 | AK5: =IF(AJ5=0, 0, AI5/AJ5*100) -> 67.802727 | AL5: =SUMIFS('21SepTo27Sep'!$L:$L, '21SepTo27Sep'!$J:$J, $A5) -> 13 | AM5: =SUMIFS('21SepTo27Sep'!$K:$K, '21SepTo27Sep'!$J:$J, $A5) -> 1322 | AN5: =SUMIFS('21SepTo27Sep'!$O:$O, '21SepTo27Sep'!$J:$J, $A5) -> 37.97 | AO5: =SUMIFS('21SepTo27Sep'!$P:$P, '21SepTo27Sep'!$J:$J, $A5) -> 124.7 | AP5: =IF(AO5=0, 0, AN5/AO5*100) -> 30.449078 | AQ5: =SUMIFS('14SepTo20Sep'!$L:$L, '14SepTo20Sep'!$J:$J, $A5) -> 17 | AR5: =SUMIFS('14SepTo20Sep'!$K:$K, '14SepTo20Sep'!$J:$J, $A5) -> 1538 | AS5: =SUMIFS('14SepTo20Sep'!$O:$O, '14SepTo20Sep'!$J:$J, $A5) -> 72.65 | AT5: =SUMIFS('14SepTo20Sep'!$P:$P, '14SepTo20Sep'!$J:$J, $A5) -> 99.76 | AU5: =IF(AT5=0, 0, AS5/AT5*100) -> 72.824779 | AV5: =SUMIFS('7SepTo13Sep'!$L:$L, '7SepTo13Sep'!$J:$J, $A5) -> 0 | AW5: =SUMIFS('7SepTo13Sep'!$K:$K, '7SepTo13Sep'!$J:$J, $A5) -> 0 | AX5: =SUMIFS('7SepTo13Sep'!$O:$O, '7SepTo13Sep'!$J:$J, $A5) -> 0 | AY5: =SUMIFS('7SepTo13Sep'!$P:$P, '7SepTo13Sep'!$J:$J, $A5) -> 0 | AZ5: =IF(AY5=0, 0, AX5/AY5*100) -> 0 | BA5: =SUMIFS('31AugTo6Sep'!$L:$L, '31AugTo6Sep'!$J:$J, $A5) -> 9 | BB5: =SUMIFS('31AugTo6Sep'!$K:$K, '31AugTo6Sep'!$J:$J, $A5) -> 960 | BC5: =SUMIFS('31AugTo6Sep'!$O:$O, '31AugTo6Sep'!$J:$J, $A5) -> 30.18 | BD5: =SUMIFS('31AugTo6Sep'!$P:$P, '31AugTo6Sep'!$J:$J, $A5) -> 174.58 | BE5: =IF(BD5=0, 0, BC5/BD5*100) -> 17.287204 | BF5: =SUMIFS('24AugTo29Aug'!$L:$L, '24AugTo29Aug'!$J:$J, $A5) -> 7 | BG5: =SUMIFS('24AugTo29Aug'!$K:$K, '24AugTo29Aug'!$J:$J, $A5) -> 418 | BH5: =SUMIFS('24AugTo29Aug'!$O:$O, '24AugTo29Aug'!$J:$J, $A5) -> 19.48 | BI5: =SUMIFS('24AugTo29Aug'!$P:$P, '24AugTo29Aug'!$J:$J, $A5) -> 74.82 | BJ5: =IF(BI5=0, 0, BH5/BI5*100) -> 26.035819 | BK5: =SUMIFS('17AugTo21Aug'!$L:$L, '17AugTo21Aug'!$J:$J, $A5) -> 14 | BL5: =SUMIFS('17AugTo21Aug'!$K:$K, '17AugTo21Aug'!$J:$J, $A5) -> 766 | BM5: =SUMIFS('17AugTo21Aug'!$O:$O, '17AugTo21Aug'!$J:$J, $A5) -> 47.2 | BN5: =SUMIFS('17AugTo21Aug'!$P:$P, '17AugTo21Aug'!$J:$J, $A5) -> 99.76 | BO5: =IF(BN5=0, 0, BM5/BN5*100) -> 47.313553 | BP5: =SUMIFS('10AugTo16Aug'!$L:$L, '10AugTo16Aug'!$J:$J, $A5) -> 6 | BQ5: =SUMIFS('10AugTo16Aug'!$K:$K, '10AugTo16Aug'!$J:$J, $A5) -> 293 | BR5: =SUMIFS('10AugTo16Aug'!$O:$O, '10AugTo16Aug'!$J:$J, $A5) -> 18.04 | BS5: =SUMIFS('10AugTo16Aug'!$P:$P, '10AugTo16Aug'!$J:$J, $A5) -> 49.88 | BT5: =IF(BS5=0, 0, BR5/BS5*100) -> 36.1668 | BU5: =SUMIFS('3AugTo9Aug'!$L:$L, '3AugTo9Aug'!$J:$J, $A5) -> 15 | BV5: =SUMIFS('3AugTo9Aug'!$K:$K, '3AugTo9Aug'!$J:$J, $A5) -> 1045 | BW5: =SUMIFS('3AugTo9Aug'!$O:$O, '3AugTo9Aug'!$J:$J, $A5) -> 41.35 | BX5: =SUMIFS('3AugTo9Aug'!$P:$P, '3AugTo9Aug'!$J:$J, $A5) -> 99.76 | BY5: =IF(BX5=0, 0, BW5/BX5*100) -> 41.449479 | BZ5: =SUMIFS('27JulyTo2Aug'!$L:$L, '27JulyTo2Aug'!$J:$J, $A5) -> 25 | CA5: =SUMIFS('27JulyTo2Aug'!$K:$K, '27JulyTo2Aug'!$J:$J, $A5) -> 1127 | CB5: =SUMIFS('27JulyTo2Aug'!$O:$O, '27JulyTo2Aug'!$J:$J, $A5) -> 80.07 | CC5: =SUMIFS('27JulyTo2Aug'!$P:$P, '27JulyTo2Aug'!$J:$J, $A5) -> 199.52 | CD5: =IF(CC5=0, 0, CB5/CC5*100) -> 40.131315
A6: maca root capsules | B6: =IF( (E6+J6+O6+T6+Y6)=0, "NO TRAFFIC", IF( (F6+K6+P6+U6+Z6)=0, "CLICKS NO SALES", IF( ((E6+J6+O6+T6+Y6)/(F6+K6+P6+U6+Z6)*100)<=35, "WINNER", "HIGH ACOS" ) ) ) -> WINNER | C6: =SUMIFS('9NovTo15Nov'!$L:$L, '9NovTo15Nov'!$J:$J, $A6) -> 5 | D6: =SUMIFS('9NovTo15Nov'!$K:$K, '9NovTo15Nov'!$J:$J, $A6) -> 360 | E6: =SUMIFS('9NovTo15Nov'!$O:$O, '9NovTo15Nov'!$J:$J, $A6) -> 18.54 | F6: =SUMIFS('9NovTo15Nov'!$P:$P, '9NovTo15Nov'!$J:$J, $A6) -> 74.82 | G6: =IF(F6=0, 0, E6/F6*100) -> 24.779471 | H6: =SUMIFS('2NovTo8Nov'!$L:$L, '2NovTo8Nov'!$J:$J, $A6) -> 0 | I6: =SUMIFS('2NovTo8Nov'!$K:$K, '2NovTo8Nov'!$J:$J, $A6) -> 0 | J6: =SUMIFS('2NovTo8Nov'!$O:$O, '2NovTo8Nov'!$J:$J, $A6) -> 0 | K6: =SUMIFS('2NovTo8Nov'!$P:$P, '2NovTo8Nov'!$J:$J, $A6) -> 0 | L6: =IF(K6=0, 0, J6/K6*100) -> 0 | M6: =SUMIFS('26OctTo1Nov'!$L:$L, '26OctTo1Nov'!$J:$J, $A6) -> 7 | N6: =SUMIFS('26OctTo1Nov'!$K:$K, '26OctTo1Nov'!$J:$J, $A6) -> 506 | O6: =SUMIFS('26OctTo1Nov'!$O:$O, '26OctTo1Nov'!$J:$J, $A6) -> 29.4 | P6: =SUMIFS('26OctTo1Nov'!$P:$P, '26OctTo1Nov'!$J:$J, $A6) -> 99.76 | Q6: =IF(P6=0, 0, O6/P6*100) -> 29.47073 | R6: =SUMIFS('19OctTo25Oct'!$L:$L, '19OctTo25Oct'!$J:$J, $A6) -> 0 | S6: =SUMIFS('19OctTo25Oct'!$K:$K, '19OctTo25Oct'!$J:$J, $A6) -> 0 | T6: =SUMIFS('19OctTo25Oct'!$O:$O, '19OctTo25Oct'!$J:$J, $A6) -> 0 | U6: =SUMIFS('19OctTo25Oct'!$P:$P, '19OctTo25Oct'!$J:$J, $A6) -> 0 | V6: =IF(U6=0, 0, T6/U6*100) -> 0 | W6: =SUMIFS('12OctTo18Oct'!$L:$L, '12OctTo18Oct'!$J:$J, $A6) -> 4 | X6: =SUMIFS('12OctTo18Oct'!$K:$K, '12OctTo18Oct'!$J:$J, $A6) -> 242 | Y6: =SUMIFS('12OctTo18Oct'!$O:$O, '12OctTo18Oct'!$J:$J, $A6) -> 16.08 | Z6: =SUMIFS('12OctTo18Oct'!$P:$P, '12OctTo18Oct'!$J:$J, $A6) -> 24.94 | AA6: =IF(Z6=0, 0, Y6/Z6*100) -> 64.474739 | AB6: =SUMIFS('5OctTo11Oct'!$L:$L, '5OctTo11Oct'!$J:$J, $A6) -> 3 | AC6: =SUMIFS('5OctTo11Oct'!$K:$K, '5OctTo11Oct'!$J:$J, $A6) -> 75 | AD6: =SUMIFS('5OctTo11Oct'!$O:$O, '5OctTo11Oct'!$J:$J, $A6) -> 8.15 | AE6: =SUMIFS('5OctTo11Oct'!$P:$P, '5OctTo11Oct'!$J:$J, $A6) -> 24.94 | AF6: =IF(AE6=0, 0, AD6/AE6*100) -> 32.678428 | AG6: =SUMIFS('28SepTo4Oct'!$L:$L, '28SepTo4Oct'!$J:$J, $A6) -> 4 | AH6: =SUMIFS('28SepTo4Oct'!$K:$K, '28SepTo4Oct'!$J:$J, $A6) -> 203 | AI6: =SUMIFS('28SepTo4Oct'!$O:$O, '28SepTo4Oct'!$J:$J, $A6) -> 15.04 | AJ6: =SUMIFS('28SepTo4Oct'!$P:$P, '28SepTo4Oct'!$J:$J, $A6) -> 24.94 | AK6: =IF(AJ6=0, 0, AI6/AJ6*100) -> 60.304731 | AL6: =SUMIFS('21SepTo27Sep'!$L:$L, '21SepTo27Sep'!$J:$J, $A6) -> 5 | AM6: =SUMIFS('21SepTo27Sep'!$K:$K, '21SepTo27Sep'!$J:$J, $A6) -> 151 | AN6: =SUMIFS('21SepTo27Sep'!$O:$O, '21SepTo27Sep'!$J:$J, $A6) -> 21.44 | AO6: =SUMIFS('21SepTo27Sep'!$P:$P, '21SepTo27Sep'!$J:$J, $A6) -> 24.94 | AP6: =IF(AO6=0, 0, AN6/AO6*100) -> 85.966319 | AQ6: =SUMIFS('14SepTo20Sep'!$L:$L, '14SepTo20Sep'!$J:$J, $A6) -> 0 | AR6: =SUMIFS('14SepTo20Sep'!$K:$K, '14SepTo20Sep'!$J:$J, $A6) -> 0 | AS6: =SUMIFS('14SepTo20Sep'!$O:$O, '14SepTo20Sep'!$J:$J, $A6) -> 0 | AT6: =SUMIFS('14SepTo20Sep'!$P:$P, '14SepTo20Sep'!$J:$J, $A6) -> 0 | AU6: =IF(AT6=0, 0, AS6/AT6*100) -> 0 | AV6: =SUMIFS('7SepTo13Sep'!$L:$L, '7SepTo13Sep'!$J:$J, $A6) -> 0 | AW6: =SUMIFS('7SepTo13Sep'!$K:$K, '7SepTo13Sep'!$J:$J, $A6) -> 0 | AX6: =SUMIFS('7SepTo13Sep'!$O:$O, '7SepTo13Sep'!$J:$J, $A6) -> 0 | AY6: =SUMIFS('7SepTo13Sep'!$P:$P, '7SepTo13Sep'!$J:$J, $A6) -> 0 | AZ6: =IF(AY6=0, 0, AX6/AY6*100) -> 0 | BA6: =SUMIFS('31AugTo6Sep'!$L:$L, '31AugTo6Sep'!$J:$J, $A6) -> 0 | BB6: =SUMIFS('31AugTo6Sep'!$K:$K, '31AugTo6Sep'!$J:$J, $A6) -> 0 | BC6: =SUMIFS('31AugTo6Sep'!$O:$O, '31AugTo6Sep'!$J:$J, $A6) -> 0 | BD6: =SUMIFS('31AugTo6Sep'!$P:$P, '31AugTo6Sep'!$J:$J, $A6) -> 0 | BE6: =IF(BD6=0, 0, BC6/BD6*100) -> 0 | BF6: =SUMIFS('24AugTo29Aug'!$L:$L, '24AugTo29Aug'!$J:$J, $A6) -> 0 | BG6: =SUMIFS('24AugTo29Aug'!$K:$K, '24AugTo29Aug'!$J:$J, $A6) -> 0 | BH6: =SUMIFS('24AugTo29Aug'!$O:$O, '24AugTo29Aug'!$J:$J, $A6) -> 0 | BI6: =SUMIFS('24AugTo29Aug'!$P:$P, '24AugTo29Aug'!$J:$J, $A6) -> 0 | BJ6: =IF(BI6=0, 0, BH6/BI6*100) -> 0 | BK6: =SUMIFS('17AugTo21Aug'!$L:$L, '17AugTo21Aug'!$J:$J, $A6) -> 0 | BL6: =SUMIFS('17AugTo21Aug'!$K:$K, '17AugTo21Aug'!$J:$J, $A6) -> 0 | BM6: =SUMIFS('17AugTo21Aug'!$O:$O, '17AugTo21Aug'!$J:$J, $A6) -> 0 | BN6: =SUMIFS('17AugTo21Aug'!$P:$P, '17AugTo21Aug'!$J:$J, $A6) -> 0 | BO6: =IF(BN6=0, 0, BM6/BN6*100) -> 0 | BP6: =SUMIFS('10AugTo16Aug'!$L:$L, '10AugTo16Aug'!$J:$J, $A6) -> 0 | BQ6: =SUMIFS('10AugTo16Aug'!$K:$K, '10AugTo16Aug'!$J:$J, $A6) -> 0 | BR6: =SUMIFS('10AugTo16Aug'!$O:$O, '10AugTo16Aug'!$J:$J, $A6) -> 0 | BS6: =SUMIFS('10AugTo16Aug'!$P:$P, '10AugTo16Aug'!$J:$J, $A6) -> 0 | BT6: =IF(BS6=0, 0, BR6/BS6*100) -> 0 | BU6: =SUMIFS('3AugTo9Aug'!$L:$L, '3AugTo9Aug'!$J:$J, $A6) -> 6 | BV6: =SUMIFS('3AugTo9Aug'!$K:$K, '3AugTo9Aug'!$J:$J, $A6) -> 89 | BW6: =SUMIFS('3AugTo9Aug'!$O:$O, '3AugTo9Aug'!$J:$J, $A6) -> 16.57 | BX6: =SUMIFS('3AugTo9Aug'!$P:$P, '3AugTo9Aug'!$J:$J, $A6) -> 24.94 | BY6: =IF(BX6=0, 0, BW6/BX6*100) -> 66.439455 | BZ6: =SUMIFS('27JulyTo2Aug'!$L:$L, '27JulyTo2Aug'!$J:$J, $A6) -> 0 | CA6: =SUMIFS('27JulyTo2Aug'!$K:$K, '27JulyTo2Aug'!$J:$J, $A6) -> 0 | CB6: =SUMIFS('27JulyTo2Aug'!$O:$O, '27JulyTo2Aug'!$J:$J, $A6) -> 0 | CC6: =SUMIFS('27JulyTo2Aug'!$P:$P, '27JulyTo2Aug'!$J:$J, $A6) -> 0 | CD6: =IF(CC6=0, 0, CB6/CC6*100) -> 0
A7: saffron and ashwagandha supplements | B7: =IF( (E7+J7+O7+T7+Y7)=0, "NO TRAFFIC", IF( (F7+K7+P7+U7+Z7)=0, "CLICKS NO SALES", IF( ((E7+J7+O7+T7+Y7)/(F7+K7+P7+U7+Z7)*100)<=35, "WINNER", "HIGH ACOS" ) ) ) -> HIGH ACOS | C7: =SUMIFS('9NovTo15Nov'!$L:$L, '9NovTo15Nov'!$J:$J, $A7) -> 7 | D7: =SUMIFS('9NovTo15Nov'!$K:$K, '9NovTo15Nov'!$J:$J, $A7) -> 52 | E7: =SUMIFS('9NovTo15Nov'!$O:$O, '9NovTo15Nov'!$J:$J, $A7) -> 31.66 | F7: =SUMIFS('9NovTo15Nov'!$P:$P, '9NovTo15Nov'!$J:$J, $A7) -> 43.8 | G7: =IF(F7=0, 0, E7/F7*100) -> 72.283105 | H7: =SUMIFS('2NovTo8Nov'!$L:$L, '2NovTo8Nov'!$J:$J, $A7) -> 2 | I7: =SUMIFS('2NovTo8Nov'!$K:$K, '2NovTo8Nov'!$J:$J, $A7) -> 11 | J7: =SUMIFS('2NovTo8Nov'!$O:$O, '2NovTo8Nov'!$J:$J, $A7) -> 10.36 | K7: =SUMIFS('2NovTo8Nov'!$P:$P, '2NovTo8Nov'!$J:$J, $A7) -> 21.9 | L7: =IF(K7=0, 0, J7/K7*100) -> 47.305936 | M7: =SUMIFS('26OctTo1Nov'!$L:$L, '26OctTo1Nov'!$J:$J, $A7) -> 7 | N7: =SUMIFS('26OctTo1Nov'!$K:$K, '26OctTo1Nov'!$J:$J, $A7) -> 92 | O7: =SUMIFS('26OctTo1Nov'!$O:$O, '26OctTo1Nov'!$J:$J, $A7) -> 26.67 | P7: =SUMIFS('26OctTo1Nov'!$P:$P, '26OctTo1Nov'!$J:$J, $A7) -> 65.7 | Q7: =IF(P7=0, 0, O7/P7*100) -> 40.593607 | R7: =SUMIFS('19OctTo25Oct'!$L:$L, '19OctTo25Oct'!$J:$J, $A7) -> 6 | S7: =SUMIFS('19OctTo25Oct'!$K:$K, '19OctTo25Oct'!$J:$J, $A7) -> 116 | T7: =SUMIFS('19OctTo25Oct'!$O:$O, '19OctTo25Oct'!$J:$J, $A7) -> 25.46 | U7: =SUMIFS('19OctTo25Oct'!$P:$P, '19OctTo25Oct'!$J:$J, $A7) -> 21.9 | V7: =IF(U7=0, 0, T7/U7*100) -> 116.25571 | W7: =SUMIFS('12OctTo18Oct'!$L:$L, '12OctTo18Oct'!$J:$J, $A7) -> 4 | X7: =SUMIFS('12OctTo18Oct'!$K:$K, '12OctTo18Oct'!$J:$J, $A7) -> 50 | Y7: =SUMIFS('12OctTo18Oct'!$O:$O, '12OctTo18Oct'!$J:$J, $A7) -> 14.29 | Z7: =SUMIFS('12OctTo18Oct'!$P:$P, '12OctTo18Oct'!$J:$J, $A7) -> 21.9 | AA7: =IF(Z7=0, 0, Y7/Z7*100) -> 65.251142 | AB7: =SUMIFS('5OctTo11Oct'!$L:$L, '5OctTo11Oct'!$J:$J, $A7) -> 0 | AC7: =SUMIFS('5OctTo11Oct'!$K:$K, '5OctTo11Oct'!$J:$J, $A7) -> 0 | AD7: =SUMIFS('5OctTo11Oct'!$O:$O, '5OctTo11Oct'!$J:$J, $A7) -> 0 | AE7: =SUMIFS('5OctTo11Oct'!$P:$P, '5OctTo11Oct'!$J:$J, $A7) -> 0 | AF7: =IF(AE7=0, 0, AD7/AE7*100) -> 0 | AG7: =SUMIFS('28SepTo4Oct'!$L:$L, '28SepTo4Oct'!$J:$J, $A7) -> 0 | AH7: =SUMIFS('28SepTo4Oct'!$K:$K, '28SepTo4Oct'!$J:$J, $A7) -> 0 | AI7: =SUMIFS('28SepTo4Oct'!$O:$O, '28SepTo4Oct'!$J:$J, $A7) -> 0 | AJ7: =SUMIFS('28SepTo4Oct'!$P:$P, '28SepTo4Oct'!$J:$J, $A7) -> 0 | AK7: =IF(AJ7=0, 0, AI7/AJ7*100) -> 0 | AL7: =SUMIFS('21SepTo27Sep'!$L:$L, '21SepTo27Sep'!$J:$J, $A7) -> 0 | AM7: =SUMIFS('21SepTo27Sep'!$K:$K, '21SepTo27Sep'!$J:$J, $A7) -> 0 | AN7: =SUMIFS('21SepTo27Sep'!$O:$O, '21SepTo27Sep'!$J:$J, $A7) -> 0 | AO7: =SUMIFS('21SepTo27Sep'!$P:$P, '21SepTo27Sep'!$J:$J, $A7) -> 0 | AP7: =IF(AO7=0, 0, AN7/AO7*100) -> 0 | AQ7: =SUMIFS('14SepTo20Sep'!$L:$L, '14SepTo20Sep'!$J:$J, $A7) -> 0 | AR7: =SUMIFS('14SepTo20Sep'!$K:$K, '14SepTo20Sep'!$J:$J, $A7) -> 0 | AS7: =SUMIFS('14SepTo20Sep'!$O:$O, '14SepTo20Sep'!$J:$J, $A7) -> 0 | AT7: =SUMIFS('14SepTo20Sep'!$P:$P, '14SepTo20Sep'!$J:$J, $A7) -> 0 | AU7: =IF(AT7=0, 0, AS7/AT7*100) -> 0 | AV7: =SUMIFS('7SepTo13Sep'!$L:$L, '7SepTo13Sep'!$J:$J, $A7) -> 0 | AW7: =SUMIFS('7SepTo13Sep'!$K:$K, '7SepTo13Sep'!$J:$J, $A7) -> 0 | AX7: =SUMIFS('7SepTo13Sep'!$O:$O, '7SepTo13Sep'!$J:$J, $A7) -> 0 | AY7: =SUMIFS('7SepTo13Sep'!$P:$P, '7SepTo13Sep'!$J:$J, $A7) -> 0 | AZ7: =IF(AY7=0, 0, AX7/AY7*100) -> 0 | BA7: =SUMIFS('31AugTo6Sep'!$L:$L, '31AugTo6Sep'!$J:$J, $A7) -> 3 | BB7: =SUMIFS('31AugTo6Sep'!$K:$K, '31AugTo6Sep'!$J:$J, $A7) -> 16 | BC7: =SUMIFS('31AugTo6Sep'!$O:$O, '31AugTo6Sep'!$J:$J, $A7) -> 9.28 | BD7: =SUMIFS('31AugTo6Sep'!$P:$P, '31AugTo6Sep'!$J:$J, $A7) -> 21.9 | BE7: =IF(BD7=0, 0, BC7/BD7*100) -> 42.374429 | BF7: =SUMIFS('24AugTo29Aug'!$L:$L, '24AugTo29Aug'!$J:$J, $A7) -> 0 | BG7: =SUMIFS('24AugTo29Aug'!$K:$K, '24AugTo29Aug'!$J:$J, $A7) -> 0 | BH7: =SUMIFS('24AugTo29Aug'!$O:$O, '24AugTo29Aug'!$J:$J, $A7) -> 0 | BI7: =SUMIFS('24AugTo29Aug'!$P:$P, '24AugTo29Aug'!$J:$J, $A7) -> 0 | BJ7: =IF(BI7=0, 0, BH7/BI7*100) -> 0 | BK7: =SUMIFS('17AugTo21Aug'!$L:$L, '17AugTo21Aug'!$J:$J, $A7) -> 2 | BL7: =SUMIFS('17AugTo21Aug'!$K:$K, '17AugTo21Aug'!$J:$J, $A7) -> 34 | BM7: =SUMIFS('17AugTo21Aug'!$O:$O, '17AugTo21Aug'!$J:$J, $A7) -> 7.29 | BN7: =SUMIFS('17AugTo21Aug'!$P:$P, '17AugTo21Aug'!$J:$J, $A7) -> 21.95 | BO7: =IF(BN7=0, 0, BM7/BN7*100) -> 33.211845 | BP7: =SUMIFS('10AugTo16Aug'!$L:$L, '10AugTo16Aug'!$J:$J, $A7) -> 0 | BQ7: =SUMIFS('10AugTo16Aug'!$K:$K, '10AugTo16Aug'!$J:$J, $A7) -> 0 | BR7: =SUMIFS('10AugTo16Aug'!$O:$O, '10AugTo16Aug'!$J:$J, $A7) -> 0 | BS7: =SUMIFS('10AugTo16Aug'!$P:$P, '10AugTo16Aug'!$J:$J, $A7) -> 0 | BT7: =IF(BS7=0, 0, BR7/BS7*100) -> 0 | BU7: =SUMIFS('3AugTo9Aug'!$L:$L, '3AugTo9Aug'!$J:$J, $A7) -> 8 | BV7: =SUMIFS('3AugTo9Aug'!$K:$K, '3AugTo9Aug'!$J:$J, $A7) -> 65 | BW7: =SUMIFS('3AugTo9Aug'!$O:$O, '3AugTo9Aug'!$J:$J, $A7) -> 24.17 | BX7: =SUMIFS('3AugTo9Aug'!$P:$P, '3AugTo9Aug'!$J:$J, $A7) -> 24.95 | BY7: =IF(BX7=0, 0, BW7/BX7*100) -> 96.873747 | BZ7: =SUMIFS('27JulyTo2Aug'!$L:$L, '27JulyTo2Aug'!$J:$J, $A7) -> 8 | CA7: =SUMIFS('27JulyTo2Aug'!$K:$K, '27JulyTo2Aug'!$J:$J, $A7) -> 25 | CB7: =SUMIFS('27JulyTo2Aug'!$O:$O, '27JulyTo2Aug'!$J:$J, $A7) -> 24.76 | CC7: =SUMIFS('27JulyTo2Aug'!$P:$P, '27JulyTo2Aug'!$J:$J, $A7) -> 99.8 | CD7: =IF(CC7=0, 0, CB7/CC7*100) -> 24.809619
A8: saffron ashwagandha supplements | B8: =IF( (E8+J8+O8+T8+Y8)=0, "NO TRAFFIC", IF( (F8+K8+P8+U8+Z8)=0, "CLICKS NO SALES", IF( ((E8+J8+O8+T8+Y8)/(F8+K8+P8+U8+Z8)*100)<=35, "WINNER", "HIGH ACOS" ) ) ) -> HIGH ACOS | C8: =SUMIFS('9NovTo15Nov'!$L:$L, '9NovTo15Nov'!$J:$J, $A8) -> 2 | D8: =SUMIFS('9NovTo15Nov'!$K:$K, '9NovTo15Nov'!$J:$J, $A8) -> 12 | E8: =SUMIFS('9NovTo15Nov'!$O:$O, '9NovTo15Nov'!$J:$J, $A8) -> 6.07 | F8: =SUMIFS('9NovTo15Nov'!$P:$P, '9NovTo15Nov'!$J:$J, $A8) -> 21.9 | G8: =IF(F8=0, 0, E8/F8*100) -> 27.716895 | H8: =SUMIFS('2NovTo8Nov'!$L:$L, '2NovTo8Nov'!$J:$J, $A8) -> 0 | I8: =SUMIFS('2NovTo8Nov'!$K:$K, '2NovTo8Nov'!$J:$J, $A8) -> 0 | J8: =SUMIFS('2NovTo8Nov'!$O:$O, '2NovTo8Nov'!$J:$J, $A8) -> 0 | K8: =SUMIFS('2NovTo8Nov'!$P:$P, '2NovTo8Nov'!$J:$J, $A8) -> 0 | L8: =IF(K8=0, 0, J8/K8*100) -> 0 | M8: =SUMIFS('26OctTo1Nov'!$L:$L, '26OctTo1Nov'!$J:$J, $A8) -> 7 | N8: =SUMIFS('26OctTo1Nov'!$K:$K, '26OctTo1Nov'!$J:$J, $A8) -> 48 | O8: =SUMIFS('26OctTo1Nov'!$O:$O, '26OctTo1Nov'!$J:$J, $A8) -> 26.3 | P8: =SUMIFS('26OctTo1Nov'!$P:$P, '26OctTo1Nov'!$J:$J, $A8) -> 21.9 | Q8: =IF(P8=0, 0, O8/P8*100) -> 120.09132 | R8: =SUMIFS('19OctTo25Oct'!$L:$L, '19OctTo25Oct'!$J:$J, $A8) -> 0 | S8: =SUMIFS('19OctTo25Oct'!$K:$K, '19OctTo25Oct'!$J:$J, $A8) -> 0 | T8: =SUMIFS('19OctTo25Oct'!$O:$O, '19OctTo25Oct'!$J:$J, $A8) -> 0 | U8: =SUMIFS('19OctTo25Oct'!$P:$P, '19OctTo25Oct'!$J:$J, $A8) -> 0 | V8: =IF(U8=0, 0, T8/U8*100) -> 0 | W8: =SUMIFS('12OctTo18Oct'!$L:$L, '12OctTo18Oct'!$J:$J, $A8) -> 0 | X8: =SUMIFS('12OctTo18Oct'!$K:$K, '12OctTo18Oct'!$J:$J, $A8) -> 0 | Y8: =SUMIFS('12OctTo18Oct'!$O:$O, '12OctTo18Oct'!$J:$J, $A8) -> 0 | Z8: =SUMIFS('12OctTo18Oct'!$P:$P, '12OctTo18Oct'!$J:$J, $A8) -> 0 | AA8: =IF(Z8=0, 0, Y8/Z8*100) -> 0 | AB8: =SUMIFS('5OctTo11Oct'!$L:$L, '5OctTo11Oct'!$J:$J, $A8) -> 0 | AC8: =SUMIFS('5OctTo11Oct'!$K:$K, '5OctTo11Oct'!$J:$J, $A8) -> 0 | AD8: =SUMIFS('5OctTo11Oct'!$O:$O, '5OctTo11Oct'!$J:$J, $A8) -> 0 | AE8: =SUMIFS('5OctTo11Oct'!$P:$P, '5OctTo11Oct'!$J:$J, $A8) -> 0 | AF8: =IF(AE8=0, 0, AD8/AE8*100) -> 0 | AG8: =SUMIFS('28SepTo4Oct'!$L:$L, '28SepTo4Oct'!$J:$J, $A8) -> 0 | AH8: =SUMIFS('28SepTo4Oct'!$K:$K, '28SepTo4Oct'!$J:$J, $A8) -> 0 | AI8: =SUMIFS('28SepTo4Oct'!$O:$O, '28SepTo4Oct'!$J:$J, $A8) -> 0 | AJ8: =SUMIFS('28SepTo4Oct'!$P:$P, '28SepTo4Oct'!$J:$J, $A8) -> 0 | AK8: =IF(AJ8=0, 0, AI8/AJ8*100) -> 0 | AL8: =SUMIFS('21SepTo27Sep'!$L:$L, '21SepTo27Sep'!$J:$J, $A8) -> 0 | AM8: =SUMIFS('21SepTo27Sep'!$K:$K, '21SepTo27Sep'!$J:$J, $A8) -> 0 | AN8: =SUMIFS('21SepTo27Sep'!$O:$O, '21SepTo27Sep'!$J:$J, $A8) -> 0 | AO8: =SUMIFS('21SepTo27Sep'!$P:$P, '21SepTo27Sep'!$J:$J, $A8) -> 0 | AP8: =IF(AO8=0, 0, AN8/AO8*100) -> 0 | AQ8: =SUMIFS('14SepTo20Sep'!$L:$L, '14SepTo20Sep'!$J:$J, $A8) -> 0 | AR8: =SUMIFS('14SepTo20Sep'!$K:$K, '14SepTo20Sep'!$J:$J, $A8) -> 0 | AS8: =SUMIFS('14SepTo20Sep'!$O:$O, '14SepTo20Sep'!$J:$J, $A8) -> 0 | AT8: =SUMIFS('14SepTo20Sep'!$P:$P, '14SepTo20Sep'!$J:$J, $A8) -> 0 | AU8: =IF(AT8=0, 0, AS8/AT8*100) -> 0 | AV8: =SUMIFS('7SepTo13Sep'!$L:$L, '7SepTo13Sep'!$J:$J, $A8) -> 2 | AW8: =SUMIFS('7SepTo13Sep'!$K:$K, '7SepTo13Sep'!$J:$J, $A8) -> 2 | AX8: =SUMIFS('7SepTo13Sep'!$O:$O, '7SepTo13Sep'!$J:$J, $A8) -> 7.58 | AY8: =SUMIFS('7SepTo13Sep'!$P:$P, '7SepTo13Sep'!$J:$J, $A8) -> 43.8 | AZ8: =IF(AY8=0, 0, AX8/AY8*100) -> 17.305936 | BA8: =SUMIFS('31AugTo6Sep'!$L:$L, '31AugTo6Sep'!$J:$J, $A8) -> 3 | BB8: =SUMIFS('31AugTo6Sep'!$K:$K, '31AugTo6Sep'!$J:$J, $A8) -> 10 | BC8: =SUMIFS('31AugTo6Sep'!$O:$O, '31AugTo6Sep'!$J:$J, $A8) -> 10.63 | BD8: =SUMIFS('31AugTo6Sep'!$P:$P, '31AugTo6Sep'!$J:$J, $A8) -> 21.9 | BE8: =IF(BD8=0, 0, BC8/BD8*100) -> 48.538813 | BF8: =SUMIFS('24AugTo29Aug'!$L:$L, '24AugTo29Aug'!$J:$J, $A8) -> 0 | BG8: =SUMIFS('24AugTo29Aug'!$K:$K, '24AugTo29Aug'!$J:$J, $A8) -> 0 | BH8: =SUMIFS('24AugTo29Aug'!$O:$O, '24AugTo29Aug'!$J:$J, $A8) -> 0 | BI8: =SUMIFS('24AugTo29Aug'!$P:$P, '24AugTo29Aug'!$J:$J, $A8) -> 0 | BJ8: =IF(BI8=0, 0, BH8/BI8*100) -> 0 | BK8: =SUMIFS('17AugTo21Aug'!$L:$L, '17AugTo21Aug'!$J:$J, $A8) -> 5 | BL8: =SUMIFS('17AugTo21Aug'!$K:$K, '17AugTo21Aug'!$J:$J, $A8) -> 20 | BM8: =SUMIFS('17AugTo21Aug'!$O:$O, '17AugTo21Aug'!$J:$J, $A8) -> 15.92 | BN8: =SUMIFS('17AugTo21Aug'!$P:$P, '17AugTo21Aug'!$J:$J, $A8) -> 43.9 | BO8: =IF(BN8=0, 0, BM8/BN8*100) -> 36.264237 | BP8: =SUMIFS('10AugTo16Aug'!$L:$L, '10AugTo16Aug'!$J:$J, $A8) -> 1 | BQ8: =SUMIFS('10AugTo16Aug'!$K:$K, '10AugTo16Aug'!$J:$J, $A8) -> 1 | BR8: =SUMIFS('10AugTo16Aug'!$O:$O, '10AugTo16Aug'!$J:$J, $A8) -> 2.45 | BS8: =SUMIFS('10AugTo16Aug'!$P:$P, '10AugTo16Aug'!$J:$J, $A8) -> 21.95 | BT8: =IF(BS8=0, 0, BR8/BS8*100) -> 11.161731 | BU8: =SUMIFS('3AugTo9Aug'!$L:$L, '3AugTo9Aug'!$J:$J, $A8) -> 2 | BV8: =SUMIFS('3AugTo9Aug'!$K:$K, '3AugTo9Aug'!$J:$J, $A8) -> 8 | BW8: =SUMIFS('3AugTo9Aug'!$O:$O, '3AugTo9Aug'!$J:$J, $A8) -> 6.77 | BX8: =SUMIFS('3AugTo9Aug'!$P:$P, '3AugTo9Aug'!$J:$J, $A8) -> 24.95 | BY8: =IF(BX8=0, 0, BW8/BX8*100) -> 27.134269 | BZ8: =SUMIFS('27JulyTo2Aug'!$L:$L, '27JulyTo2Aug'!$J:$J, $A8) -> 0 | CA8: =SUMIFS('27JulyTo2Aug'!$K:$K, '27JulyTo2Aug'!$J:$J, $A8) -> 0 | CB8: =SUMIFS('27JulyTo2Aug'!$O:$O, '27JulyTo2Aug'!$J:$J, $A8) -> 0 | CC8: =SUMIFS('27JulyTo2Aug'!$P:$P, '27JulyTo2Aug'!$J:$J, $A8) -> 0 | CD8: =IF(CC8=0, 0, CB8/CC8*100) -> 0
A9: maca root capsules for men | B9: =IF( (E9+J9+O9+T9+Y9)=0, "NO TRAFFIC", IF( (F9+K9+P9+U9+Z9)=0, "CLICKS NO SALES", IF( ((E9+J9+O9+T9+Y9)/(F9+K9+P9+U9+Z9)*100)<=35, "WINNER", "HIGH ACOS" ) ) ) -> HIGH ACOS | C9: =SUMIFS('9NovTo15Nov'!$L:$L, '9NovTo15Nov'!$J:$J, $A9) -> 3 | D9: =SUMIFS('9NovTo15Nov'!$K:$K, '9NovTo15Nov'!$J:$J, $A9) -> 1354 | E9: =SUMIFS('9NovTo15Nov'!$O:$O, '9NovTo15Nov'!$J:$J, $A9) -> 8.18 | F9: =SUMIFS('9NovTo15Nov'!$P:$P, '9NovTo15Nov'!$J:$J, $A9) -> 74.82 | G9: =IF(F9=0, 0, E9/F9*100) -> 10.932906 | H9: =SUMIFS('2NovTo8Nov'!$L:$L, '2NovTo8Nov'!$J:$J, $A9) -> 6 | I9: =SUMIFS('2NovTo8Nov'!$K:$K, '2NovTo8Nov'!$J:$J, $A9) -> 350 | J9: =SUMIFS('2NovTo8Nov'!$O:$O, '2NovTo8Nov'!$J:$J, $A9) -> 23.36 | K9: =SUMIFS('2NovTo8Nov'!$P:$P, '2NovTo8Nov'!$J:$J, $A9) -> 49.88 | L9: =IF(K9=0, 0, J9/K9*100) -> 46.832398 | M9: =SUMIFS('26OctTo1Nov'!$L:$L, '26OctTo1Nov'!$J:$J, $A9) -> 6 | N9: =SUMIFS('26OctTo1Nov'!$K:$K, '26OctTo1Nov'!$J:$J, $A9) -> 1809 | O9: =SUMIFS('26OctTo1Nov'!$O:$O, '26OctTo1Nov'!$J:$J, $A9) -> 16.2 | P9: =SUMIFS('26OctTo1Nov'!$P:$P, '26OctTo1Nov'!$J:$J, $A9) -> 24.94 | Q9: =IF(P9=0, 0, O9/P9*100) -> 64.955894 | R9: =SUMIFS('19OctTo25Oct'!$L:$L, '19OctTo25Oct'!$J:$J, $A9) -> 8 | S9: =SUMIFS('19OctTo25Oct'!$K:$K, '19OctTo25Oct'!$J:$J, $A9) -> 975 | T9: =SUMIFS('19OctTo25Oct'!$O:$O, '19OctTo25Oct'!$J:$J, $A9) -> 27.67 | U9: =SUMIFS('19OctTo25Oct'!$P:$P, '19OctTo25Oct'!$J:$J, $A9) -> 49.88 | V9: =IF(U9=0, 0, T9/U9*100) -> 55.473136 | W9: =SUMIFS('12OctTo18Oct'!$L:$L, '12OctTo18Oct'!$J:$J, $A9) -> 0 | X9: =SUMIFS('12OctTo18Oct'!$K:$K, '12OctTo18Oct'!$J:$J, $A9) -> 0 | Y9: =SUMIFS('12OctTo18Oct'!$O:$O, '12OctTo18Oct'!$J:$J, $A9) -> 0 | Z9: =SUMIFS('12OctTo18Oct'!$P:$P, '12OctTo18Oct'!$J:$J, $A9) -> 0 | AA9: =IF(Z9=0, 0, Y9/Z9*100) -> 0 | AB9: =SUMIFS('5OctTo11Oct'!$L:$L, '5OctTo11Oct'!$J:$J, $A9) -> 8 | AC9: =SUMIFS('5OctTo11Oct'!$K:$K, '5OctTo11Oct'!$J:$J, $A9) -> 1775 | AD9: =SUMIFS('5OctTo11Oct'!$O:$O, '5OctTo11Oct'!$J:$J, $A9) -> 22.56 | AE9: =SUMIFS('5OctTo11Oct'!$P:$P, '5OctTo11Oct'!$J:$J, $A9) -> 19.95 | AF9: =IF(AE9=0, 0, AD9/AE9*100) -> 113.08271 | AG9: =SUMIFS('28SepTo4Oct'!$L:$L, '28SepTo4Oct'!$J:$J, $A9) -> 0 | AH9: =SUMIFS('28SepTo4Oct'!$K:$K, '28SepTo4Oct'!$J:$J, $A9) -> 0 | AI9: =SUMIFS('28SepTo4Oct'!$O:$O, '28SepTo4Oct'!$J:$J, $A9) -> 0 | AJ9: =SUMIFS('28SepTo4Oct'!$P:$P, '28SepTo4Oct'!$J:$J, $A9) -> 0 | AK9: =IF(AJ9=0, 0, AI9/AJ9*100) -> 0 | AL9: =SUMIFS('21SepTo27Sep'!$L:$L, '21SepTo27Sep'!$J:$J, $A9) -> 6 | AM9: =SUMIFS('21SepTo27Sep'!$K:$K, '21SepTo27Sep'!$J:$J, $A9) -> 279 | AN9: =SUMIFS('21SepTo27Sep'!$O:$O, '21SepTo27Sep'!$J:$J, $A9) -> 26.77 | AO9: =SUMIFS('21SepTo27Sep'!$P:$P, '21SepTo27Sep'!$J:$J, $A9) -> 49.88 | AP9: =IF(AO9=0, 0, AN9/AO9*100) -> 53.668805 | AQ9: =SUMIFS('14SepTo20Sep'!$L:$L, '14SepTo20Sep'!$J:$J, $A9) -> 9 | AR9: =SUMIFS('14SepTo20Sep'!$K:$K, '14SepTo20Sep'!$J:$J, $A9) -> 633 | AS9: =SUMIFS('14SepTo20Sep'!$O:$O, '14SepTo20Sep'!$J:$J, $A9) -> 36.56 | AT9: =SUMIFS('14SepTo20Sep'!$P:$P, '14SepTo20Sep'!$J:$J, $A9) -> 24.94 | AU9: =IF(AT9=0, 0, AS9/AT9*100) -> 146.59182 | AV9: =SUMIFS('7SepTo13Sep'!$L:$L, '7SepTo13Sep'!$J:$J, $A9) -> 0 | AW9: =SUMIFS('7SepTo13Sep'!$K:$K, '7SepTo13Sep'!$J:$J, $A9) -> 0 | AX9: =SUMIFS('7SepTo13Sep'!$O:$O, '7SepTo13Sep'!$J:$J, $A9) -> 0 | AY9: =SUMIFS('7SepTo13Sep'!$P:$P, '7SepTo13Sep'!$J:$J, $A9) -> 0 | AZ9: =IF(AY9=0, 0, AX9/AY9*100) -> 0 | BA9: =SUMIFS('31AugTo6Sep'!$L:$L, '31AugTo6Sep'!$J:$J, $A9) -> 14 | BB9: =SUMIFS('31AugTo6Sep'!$K:$K, '31AugTo6Sep'!$J:$J, $A9) -> 1212 | BC9: =SUMIFS('31AugTo6Sep'!$O:$O, '31AugTo6Sep'!$J:$J, $A9) -> 52.6 | BD9: =SUMIFS('31AugTo6Sep'!$P:$P, '31AugTo6Sep'!$J:$J, $A9) -> 99.76 | BE9: =IF(BD9=0, 0, BC9/BD9*100) -> 52.726544 | BF9: =SUMIFS('24AugTo29Aug'!$L:$L, '24AugTo29Aug'!$J:$J, $A9) -> 14 | BG9: =SUMIFS('24AugTo29Aug'!$K:$K, '24AugTo29Aug'!$J:$J, $A9) -> 1849 | BH9: =SUMIFS('24AugTo29Aug'!$O:$O, '24AugTo29Aug'!$J:$J, $A9) -> 40 | BI9: =SUMIFS('24AugTo29Aug'!$P:$P, '24AugTo29Aug'!$J:$J, $A9) -> 24.94 | BJ9: =IF(BI9=0, 0, BH9/BI9*100) -> 160.38492 | BK9: =SUMIFS('17AugTo21Aug'!$L:$L, '17AugTo21Aug'!$J:$J, $A9) -> 10 | BL9: =SUMIFS('17AugTo21Aug'!$K:$K, '17AugTo21Aug'!$J:$J, $A9) -> 1090 | BM9: =SUMIFS('17AugTo21Aug'!$O:$O, '17AugTo21Aug'!$J:$J, $A9) -> 36.32 | BN9: =SUMIFS('17AugTo21Aug'!$P:$P, '17AugTo21Aug'!$J:$J, $A9) -> 124.7 | BO9: =IF(BN9=0, 0, BM9/BN9*100) -> 29.125902 | BP9: =SUMIFS('10AugTo16Aug'!$L:$L, '10AugTo16Aug'!$J:$J, $A9) -> 18 | BQ9: =SUMIFS('10AugTo16Aug'!$K:$K, '10AugTo16Aug'!$J:$J, $A9) -> 1819 | BR9: =SUMIFS('10AugTo16Aug'!$O:$O, '10AugTo16Aug'!$J:$J, $A9) -> 62.97 | BS9: =SUMIFS('10AugTo16Aug'!$P:$P, '10AugTo16Aug'!$J:$J, $A9) -> 144.76 | BT9: =IF(BS9=0, 0, BR9/BS9*100) -> 43.499586 | BU9: =SUMIFS('3AugTo9Aug'!$L:$L, '3AugTo9Aug'!$J:$J, $A9) -> 13 | BV9: =SUMIFS('3AugTo9Aug'!$K:$K, '3AugTo9Aug'!$J:$J, $A9) -> 2211 | BW9: =SUMIFS('3AugTo9Aug'!$O:$O, '3AugTo9Aug'!$J:$J, $A9) -> 38.21 | BX9: =SUMIFS('3AugTo9Aug'!$P:$P, '3AugTo9Aug'!$J:$J, $A9) -> 74.82 | BY9: =IF(BX9=0, 0, BW9/BX9*100) -> 51.069233 | BZ9: =SUMIFS('27JulyTo2Aug'!$L:$L, '27JulyTo2Aug'!$J:$J, $A9) -> 15 | CA9: =SUMIFS('27JulyTo2Aug'!$K:$K, '27JulyTo2Aug'!$J:$J, $A9) -> 1346 | CB9: =SUMIFS('27JulyTo2Aug'!$O:$O, '27JulyTo2Aug'!$J:$J, $A9) -> 47.85 | CC9: =SUMIFS('27JulyTo2Aug'!$P:$P, '27JulyTo2Aug'!$J:$J, $A9) -> 74.82 | CD9: =IF(CC9=0, 0, CB9/CC9*100) -> 63.953488
A10: maca root and ashwagandha | B10: =IF( (E10+J10+O10+T10+Y10)=0, "NO TRAFFIC", IF( (F10+K10+P10+U10+Z10)=0, "CLICKS NO SALES", IF( ((E10+J10+O10+T10+Y10)/(F10+K10+P10+U10+Z10)*100)<=35, "WINNER", "HIGH ACOS" ) ) ) -> WINNER | C10: =SUMIFS('9NovTo15Nov'!$L:$L, '9NovTo15Nov'!$J:$J, $A10) -> 2 | D10: =SUMIFS('9NovTo15Nov'!$K:$K, '9NovTo15Nov'!$J:$J, $A10) -> 17 | E10: =SUMIFS('9NovTo15Nov'!$O:$O, '9NovTo15Nov'!$J:$J, $A10) -> 5.35 | F10: =SUMIFS('9NovTo15Nov'!$P:$P, '9NovTo15Nov'!$J:$J, $A10) -> 24.94 | G10: =IF(F10=0, 0, E10/F10*100) -> 21.451484 | H10: =SUMIFS('2NovTo8Nov'!$L:$L, '2NovTo8Nov'!$J:$J, $A10) -> 5 | I10: =SUMIFS('2NovTo8Nov'!$K:$K, '2NovTo8Nov'!$J:$J, $A10) -> 66 | J10: =SUMIFS('2NovTo8Nov'!$O:$O, '2NovTo8Nov'!$J:$J, $A10) -> 14.93 | K10: =SUMIFS('2NovTo8Nov'!$P:$P, '2NovTo8Nov'!$J:$J, $A10) -> 24.94 | L10: =IF(K10=0, 0, J10/K10*100) -> 59.863673 | M10: =SUMIFS('26OctTo1Nov'!$L:$L, '26OctTo1Nov'!$J:$J, $A10) -> 6 | N10: =SUMIFS('26OctTo1Nov'!$K:$K, '26OctTo1Nov'!$J:$J, $A10) -> 58 | O10: =SUMIFS('26OctTo1Nov'!$O:$O, '26OctTo1Nov'!$J:$J, $A10) -> 21.81 | P10: =SUMIFS('26OctTo1Nov'!$P:$P, '26OctTo1Nov'!$J:$J, $A10) -> 74.82 | Q10: =IF(P10=0, 0, O10/P10*100) -> 29.14996 | R10: =SUMIFS('19OctTo25Oct'!$L:$L, '19OctTo25Oct'!$J:$J, $A10) -> 0 | S10: =SUMIFS('19OctTo25Oct'!$K:$K, '19OctTo25Oct'!$J:$J, $A10) -> 0 | T10: =SUMIFS('19OctTo25Oct'!$O:$O, '19OctTo25Oct'!$J:$J, $A10) -> 0 | U10: =SUMIFS('19OctTo25Oct'!$P:$P, '19OctTo25Oct'!$J:$J, $A10) -> 0 | V10: =IF(U10=0, 0, T10/U10*100) -> 0 | W10: =SUMIFS('12OctTo18Oct'!$L:$L, '12OctTo18Oct'!$J:$J, $A10) -> 0 | X10: =SUMIFS('12OctTo18Oct'!$K:$K, '12OctTo18Oct'!$J:$J, $A10) -> 0 | Y10: =SUMIFS('12OctTo18Oct'!$O:$O, '12OctTo18Oct'!$J:$J, $A10) -> 0 | Z10: =SUMIFS('12OctTo18Oct'!$P:$P, '12OctTo18Oct'!$J:$J, $A10) -> 0 | AA10: =IF(Z10=0, 0, Y10/Z10*100) -> 0 | AB10: =SUMIFS('5OctTo11Oct'!$L:$L, '5OctTo11Oct'!$J:$J, $A10) -> 0 | AC10: =SUMIFS('5OctTo11Oct'!$K:$K, '5OctTo11Oct'!$J:$J, $A10) -> 0 | AD10: =SUMIFS('5OctTo11Oct'!$O:$O, '5OctTo11Oct'!$J:$J, $A10) -> 0 | AE10: =SUMIFS('5OctTo11Oct'!$P:$P, '5OctTo11Oct'!$J:$J, $A10) -> 0 | AF10: =IF(AE10=0, 0, AD10/AE10*100) -> 0 | AG10: =SUMIFS('28SepTo4Oct'!$L:$L, '28SepTo4Oct'!$J:$J, $A10) -> 6 | AH10: =SUMIFS('28SepTo4Oct'!$K:$K, '28SepTo4Oct'!$J:$J, $A10) -> 184 | AI10: =SUMIFS('28SepTo4Oct'!$O:$O, '28SepTo4Oct'!$J:$J, $A10) -> 18.93 | AJ10: =SUMIFS('28SepTo4Oct'!$P:$P, '28SepTo4Oct'!$J:$J, $A10) -> 49.88 | AK10: =IF(AJ10=0, 0, AI10/AJ10*100) -> 37.951083 | AL10: =SUMIFS('21SepTo27Sep'!$L:$L, '21SepTo27Sep'!$J:$J, $A10) -> 7 | AM10: =SUMIFS('21SepTo27Sep'!$K:$K, '21SepTo27Sep'!$J:$J, $A10) -> 59 | AN10: =SUMIFS('21SepTo27Sep'!$O:$O, '21SepTo27Sep'!$J:$J, $A10) -> 21.49 | AO10: =SUMIFS('21SepTo27Sep'!$P:$P, '21SepTo27Sep'!$J:$J, $A10) -> 49.88 | AP10: =IF(AO10=0, 0, AN10/AO10*100) -> 43.0834 | AQ10: =SUMIFS('14SepTo20Sep'!$L:$L, '14SepTo20Sep'!$J:$J, $A10) -> 0 | AR10: =SUMIFS('14SepTo20Sep'!$K:$K, '14SepTo20Sep'!$J:$J, $A10) -> 0 | AS10: =SUMIFS('14SepTo20Sep'!$O:$O, '14SepTo20Sep'!$J:$J, $A10) -> 0 | AT10: =SUMIFS('14SepTo20Sep'!$P:$P, '14SepTo20Sep'!$J:$J, $A10) -> 0 | AU10: =IF(AT10=0, 0, AS10/AT10*100) -> 0 | AV10: =SUMIFS('7SepTo13Sep'!$L:$L, '7SepTo13Sep'!$J:$J, $A10) -> 0 | AW10: =SUMIFS('7SepTo13Sep'!$K:$K, '7SepTo13Sep'!$J:$J, $A10) -> 0 | AX10: =SUMIFS('7SepTo13Sep'!$O:$O, '7SepTo13Sep'!$J:$J, $A10) -> 0 | AY10: =SUMIFS('7SepTo13Sep'!$P:$P, '7SepTo13Sep'!$J:$J, $A10) -> 0 | AZ10: =IF(AY10=0, 0, AX10/AY10*100) -> 0 | BA10: =SUMIFS('31AugTo6Sep'!$L:$L, '31AugTo6Sep'!$J:$J, $A10) -> 3 | BB10: =SUMIFS('31AugTo6Sep'!$K:$K, '31AugTo6Sep'!$J:$J, $A10) -> 66 | BC10: =SUMIFS('31AugTo6Sep'!$O:$O, '31AugTo6Sep'!$J:$J, $A10) -> 10.05 | BD10: =SUMIFS('31AugTo6Sep'!$P:$P, '31AugTo6Sep'!$J:$J, $A10) -> 24.94 | BE10: =IF(BD10=0, 0, BC10/BD10*100) -> 40.296712 | BF10: =SUMIFS('24AugTo29Aug'!$L:$L, '24AugTo29Aug'!$J:$J, $A10) -> 0 | BG10: =SUMIFS('24AugTo29Aug'!$K:$K, '24AugTo29Aug'!$J:$J, $A10) -> 0 | BH10: =SUMIFS('24AugTo29Aug'!$O:$O, '24AugTo29Aug'!$J:$J, $A10) -> 0 | BI10: =SUMIFS('24AugTo29Aug'!$P:$P, '24AugTo29Aug'!$J:$J, $A10) -> 0 | BJ10: =IF(BI10=0, 0, BH10/BI10*100) -> 0 | BK10: =SUMIFS('17AugTo21Aug'!$L:$L, '17AugTo21Aug'!$J:$J, $A10) -> 2 | BL10: =SUMIFS('17AugTo21Aug'!$K:$K, '17AugTo21Aug'!$J:$J, $A10) -> 12 | BM10: =SUMIFS('17AugTo21Aug'!$O:$O, '17AugTo21Aug'!$J:$J, $A10) -> 6.54 | BN10: =SUMIFS('17AugTo21Aug'!$P:$P, '17AugTo21Aug'!$J:$J, $A10) -> 24.94 | BO10: =IF(BN10=0, 0, BM10/BN10*100) -> 26.222935 | BP10: =SUMIFS('10AugTo16Aug'!$L:$L, '10AugTo16Aug'!$J:$J, $A10) -> 0 | BQ10: =SUMIFS('10AugTo16Aug'!$K:$K, '10AugTo16Aug'!$J:$J, $A10) -> 0 | BR10: =SUMIFS('10AugTo16Aug'!$O:$O, '10AugTo16Aug'!$J:$J, $A10) -> 0 | BS10: =SUMIFS('10AugTo16Aug'!$P:$P, '10AugTo16Aug'!$J:$J, $A10) -> 0 | BT10: =IF(BS10=0, 0, BR10/BS10*100) -> 0 | BU10: =SUMIFS('3AugTo9Aug'!$L:$L, '3AugTo9Aug'!$J:$J, $A10) -> 6 | BV10: =SUMIFS('3AugTo9Aug'!$K:$K, '3AugTo9Aug'!$J:$J, $A10) -> 39 | BW10: =SUMIFS('3AugTo9Aug'!$O:$O, '3AugTo9Aug'!$J:$J, $A10) -> 19.83 | BX10: =SUMIFS('3AugTo9Aug'!$P:$P, '3AugTo9Aug'!$J:$J, $A10) -> 24.94 | BY10: =IF(BX10=0, 0, BW10/BX10*100) -> 79.510826 | BZ10: =SUMIFS('27JulyTo2Aug'!$L:$L, '27JulyTo2Aug'!$J:$J, $A10) -> 7 | CA10: =SUMIFS('27JulyTo2Aug'!$K:$K, '27JulyTo2Aug'!$J:$J, $A10) -> 32 | CB10: =SUMIFS('27JulyTo2Aug'!$O:$O, '27JulyTo2Aug'!$J:$J, $A10) -> 23.35 | CC10: =SUMIFS('27JulyTo2Aug'!$P:$P, '27JulyTo2Aug'!$J:$J, $A10) -> 74.82 | CD10: =IF(CC10=0, 0, CB10/CC10*100) -> 31.208233
